2023-02-09 13:17:41,606 -  nornir.core -     INFO -        run() - Running task 'show_command_test' with args {} on 7 hosts
2023-02-10 11:16:45,874 -  nornir.core -     INFO -        run() - Running task 'send_file' with args {} on 7 hosts
2023-02-10 11:17:16,497 - nornir.core.task -    ERROR -      start() - Host 'R6': task 'send_commands_from_file' failed with traceback:
Traceback (most recent call last):
  File "/home/ilya/.local/lib/python3.10/site-packages/nornir/core/task.py", line 99, in start
    r = self.task(self, **self.params)
  File "/home/ilya/.local/lib/python3.10/site-packages/nornir_scrapli/tasks/core/send_commands_from_file.py", line 43, in send_commands_from_file
    scrapli_response = scrapli_conn.send_commands_from_file(
  File "/home/ilya/.local/lib/python3.10/site-packages/scrapli/driver/network/sync_driver.py", line 347, in send_commands_from_file
    return super().send_commands_from_file(
  File "/home/ilya/.local/lib/python3.10/site-packages/scrapli/driver/generic/sync_driver.py", line 277, in send_commands_from_file
    return self.send_commands(
  File "/home/ilya/.local/lib/python3.10/site-packages/scrapli/driver/network/sync_driver.py", line 294, in send_commands
    responses = super().send_commands(
  File "/home/ilya/.local/lib/python3.10/site-packages/scrapli/driver/generic/sync_driver.py", line 215, in send_commands
    response = self._send_command(
  File "/home/ilya/.local/lib/python3.10/site-packages/scrapli/decorators.py", line 297, in decorate
    result = wrapped_func(*args, **kwargs)
  File "/home/ilya/.local/lib/python3.10/site-packages/scrapli/driver/generic/sync_driver.py", line 138, in _send_command
    raw_response, processed_response = self.channel.send_input(
  File "/home/ilya/.local/lib/python3.10/site-packages/scrapli/decorators.py", line 216, in decorate
    return _multiprocessing_timeout(
  File "/home/ilya/.local/lib/python3.10/site-packages/scrapli/decorators.py", line 108, in _multiprocessing_timeout
    return _handle_timeout(
  File "/home/ilya/.local/lib/python3.10/site-packages/scrapli/decorators.py", line 134, in _handle_timeout
    raise ScrapliTimeout(message)
scrapli.exceptions.ScrapliTimeout: timed out sending input to device

2023-02-10 11:17:16,497 - nornir.core.task -    ERROR -      start() - Host 'R6': task 'send_file' failed with traceback:
Traceback (most recent call last):
  File "/home/ilya/.local/lib/python3.10/site-packages/nornir/core/task.py", line 99, in start
    r = self.task(self, **self.params)
  File "/home/ilya/Nornir_Labs/send_from_file.py", line 8, in send_file
    task.run(task=send_commands_from_file, file="commands.txt")
  File "/home/ilya/.local/lib/python3.10/site-packages/nornir/core/task.py", line 174, in run
    raise NornirSubTaskError(task=run_task, result=r)
nornir.core.exceptions.NornirSubTaskError: Subtask: send_commands_from_file (failed)


2023-02-10 11:17:16,501 - nornir.core.task -    ERROR -      start() - Host 'R5': task 'send_commands_from_file' failed with traceback:
Traceback (most recent call last):
  File "/home/ilya/.local/lib/python3.10/site-packages/nornir/core/task.py", line 99, in start
    r = self.task(self, **self.params)
  File "/home/ilya/.local/lib/python3.10/site-packages/nornir_scrapli/tasks/core/send_commands_from_file.py", line 43, in send_commands_from_file
    scrapli_response = scrapli_conn.send_commands_from_file(
  File "/home/ilya/.local/lib/python3.10/site-packages/scrapli/driver/network/sync_driver.py", line 347, in send_commands_from_file
    return super().send_commands_from_file(
  File "/home/ilya/.local/lib/python3.10/site-packages/scrapli/driver/generic/sync_driver.py", line 277, in send_commands_from_file
    return self.send_commands(
  File "/home/ilya/.local/lib/python3.10/site-packages/scrapli/driver/network/sync_driver.py", line 294, in send_commands
    responses = super().send_commands(
  File "/home/ilya/.local/lib/python3.10/site-packages/scrapli/driver/generic/sync_driver.py", line 215, in send_commands
    response = self._send_command(
  File "/home/ilya/.local/lib/python3.10/site-packages/scrapli/decorators.py", line 297, in decorate
    result = wrapped_func(*args, **kwargs)
  File "/home/ilya/.local/lib/python3.10/site-packages/scrapli/driver/generic/sync_driver.py", line 138, in _send_command
    raw_response, processed_response = self.channel.send_input(
  File "/home/ilya/.local/lib/python3.10/site-packages/scrapli/decorators.py", line 216, in decorate
    return _multiprocessing_timeout(
  File "/home/ilya/.local/lib/python3.10/site-packages/scrapli/decorators.py", line 108, in _multiprocessing_timeout
    return _handle_timeout(
  File "/home/ilya/.local/lib/python3.10/site-packages/scrapli/decorators.py", line 134, in _handle_timeout
    raise ScrapliTimeout(message)
scrapli.exceptions.ScrapliTimeout: timed out sending input to device

2023-02-10 11:17:16,502 - nornir.core.task -    ERROR -      start() - Host 'R5': task 'send_file' failed with traceback:
Traceback (most recent call last):
  File "/home/ilya/.local/lib/python3.10/site-packages/nornir/core/task.py", line 99, in start
    r = self.task(self, **self.params)
  File "/home/ilya/Nornir_Labs/send_from_file.py", line 8, in send_file
    task.run(task=send_commands_from_file, file="commands.txt")
  File "/home/ilya/.local/lib/python3.10/site-packages/nornir/core/task.py", line 174, in run
    raise NornirSubTaskError(task=run_task, result=r)
nornir.core.exceptions.NornirSubTaskError: Subtask: send_commands_from_file (failed)


2023-02-10 11:17:16,533 - nornir.core.task -    ERROR -      start() - Host 'R4': task 'send_commands_from_file' failed with traceback:
Traceback (most recent call last):
  File "/home/ilya/.local/lib/python3.10/site-packages/nornir/core/task.py", line 99, in start
    r = self.task(self, **self.params)
  File "/home/ilya/.local/lib/python3.10/site-packages/nornir_scrapli/tasks/core/send_commands_from_file.py", line 43, in send_commands_from_file
    scrapli_response = scrapli_conn.send_commands_from_file(
  File "/home/ilya/.local/lib/python3.10/site-packages/scrapli/driver/network/sync_driver.py", line 347, in send_commands_from_file
    return super().send_commands_from_file(
  File "/home/ilya/.local/lib/python3.10/site-packages/scrapli/driver/generic/sync_driver.py", line 277, in send_commands_from_file
    return self.send_commands(
  File "/home/ilya/.local/lib/python3.10/site-packages/scrapli/driver/network/sync_driver.py", line 294, in send_commands
    responses = super().send_commands(
  File "/home/ilya/.local/lib/python3.10/site-packages/scrapli/driver/generic/sync_driver.py", line 215, in send_commands
    response = self._send_command(
  File "/home/ilya/.local/lib/python3.10/site-packages/scrapli/decorators.py", line 297, in decorate
    result = wrapped_func(*args, **kwargs)
  File "/home/ilya/.local/lib/python3.10/site-packages/scrapli/driver/generic/sync_driver.py", line 138, in _send_command
    raw_response, processed_response = self.channel.send_input(
  File "/home/ilya/.local/lib/python3.10/site-packages/scrapli/decorators.py", line 216, in decorate
    return _multiprocessing_timeout(
  File "/home/ilya/.local/lib/python3.10/site-packages/scrapli/decorators.py", line 108, in _multiprocessing_timeout
    return _handle_timeout(
  File "/home/ilya/.local/lib/python3.10/site-packages/scrapli/decorators.py", line 134, in _handle_timeout
    raise ScrapliTimeout(message)
scrapli.exceptions.ScrapliTimeout: timed out sending input to device

2023-02-10 11:17:16,533 - nornir.core.task -    ERROR -      start() - Host 'R4': task 'send_file' failed with traceback:
Traceback (most recent call last):
  File "/home/ilya/.local/lib/python3.10/site-packages/nornir/core/task.py", line 99, in start
    r = self.task(self, **self.params)
  File "/home/ilya/Nornir_Labs/send_from_file.py", line 8, in send_file
    task.run(task=send_commands_from_file, file="commands.txt")
  File "/home/ilya/.local/lib/python3.10/site-packages/nornir/core/task.py", line 174, in run
    raise NornirSubTaskError(task=run_task, result=r)
nornir.core.exceptions.NornirSubTaskError: Subtask: send_commands_from_file (failed)


2023-02-10 11:17:16,560 - nornir.core.task -    ERROR -      start() - Host 'R7': task 'send_commands_from_file' failed with traceback:
Traceback (most recent call last):
  File "/home/ilya/.local/lib/python3.10/site-packages/nornir/core/task.py", line 99, in start
    r = self.task(self, **self.params)
  File "/home/ilya/.local/lib/python3.10/site-packages/nornir_scrapli/tasks/core/send_commands_from_file.py", line 43, in send_commands_from_file
    scrapli_response = scrapli_conn.send_commands_from_file(
  File "/home/ilya/.local/lib/python3.10/site-packages/scrapli/driver/network/sync_driver.py", line 347, in send_commands_from_file
    return super().send_commands_from_file(
  File "/home/ilya/.local/lib/python3.10/site-packages/scrapli/driver/generic/sync_driver.py", line 277, in send_commands_from_file
    return self.send_commands(
  File "/home/ilya/.local/lib/python3.10/site-packages/scrapli/driver/network/sync_driver.py", line 294, in send_commands
    responses = super().send_commands(
  File "/home/ilya/.local/lib/python3.10/site-packages/scrapli/driver/generic/sync_driver.py", line 215, in send_commands
    response = self._send_command(
  File "/home/ilya/.local/lib/python3.10/site-packages/scrapli/decorators.py", line 297, in decorate
    result = wrapped_func(*args, **kwargs)
  File "/home/ilya/.local/lib/python3.10/site-packages/scrapli/driver/generic/sync_driver.py", line 138, in _send_command
    raw_response, processed_response = self.channel.send_input(
  File "/home/ilya/.local/lib/python3.10/site-packages/scrapli/decorators.py", line 216, in decorate
    return _multiprocessing_timeout(
  File "/home/ilya/.local/lib/python3.10/site-packages/scrapli/decorators.py", line 108, in _multiprocessing_timeout
    return _handle_timeout(
  File "/home/ilya/.local/lib/python3.10/site-packages/scrapli/decorators.py", line 134, in _handle_timeout
    raise ScrapliTimeout(message)
scrapli.exceptions.ScrapliTimeout: timed out sending input to device

2023-02-10 11:17:16,560 - nornir.core.task -    ERROR -      start() - Host 'R7': task 'send_file' failed with traceback:
Traceback (most recent call last):
  File "/home/ilya/.local/lib/python3.10/site-packages/nornir/core/task.py", line 99, in start
    r = self.task(self, **self.params)
  File "/home/ilya/Nornir_Labs/send_from_file.py", line 8, in send_file
    task.run(task=send_commands_from_file, file="commands.txt")
  File "/home/ilya/.local/lib/python3.10/site-packages/nornir/core/task.py", line 174, in run
    raise NornirSubTaskError(task=run_task, result=r)
nornir.core.exceptions.NornirSubTaskError: Subtask: send_commands_from_file (failed)


2023-02-10 11:17:16,579 - nornir.core.task -    ERROR -      start() - Host 'R2': task 'send_commands_from_file' failed with traceback:
Traceback (most recent call last):
  File "/home/ilya/.local/lib/python3.10/site-packages/nornir/core/task.py", line 99, in start
    r = self.task(self, **self.params)
  File "/home/ilya/.local/lib/python3.10/site-packages/nornir_scrapli/tasks/core/send_commands_from_file.py", line 43, in send_commands_from_file
    scrapli_response = scrapli_conn.send_commands_from_file(
  File "/home/ilya/.local/lib/python3.10/site-packages/scrapli/driver/network/sync_driver.py", line 347, in send_commands_from_file
    return super().send_commands_from_file(
  File "/home/ilya/.local/lib/python3.10/site-packages/scrapli/driver/generic/sync_driver.py", line 277, in send_commands_from_file
    return self.send_commands(
  File "/home/ilya/.local/lib/python3.10/site-packages/scrapli/driver/network/sync_driver.py", line 294, in send_commands
    responses = super().send_commands(
  File "/home/ilya/.local/lib/python3.10/site-packages/scrapli/driver/generic/sync_driver.py", line 215, in send_commands
    response = self._send_command(
  File "/home/ilya/.local/lib/python3.10/site-packages/scrapli/decorators.py", line 297, in decorate
    result = wrapped_func(*args, **kwargs)
  File "/home/ilya/.local/lib/python3.10/site-packages/scrapli/driver/generic/sync_driver.py", line 138, in _send_command
    raw_response, processed_response = self.channel.send_input(
  File "/home/ilya/.local/lib/python3.10/site-packages/scrapli/decorators.py", line 216, in decorate
    return _multiprocessing_timeout(
  File "/home/ilya/.local/lib/python3.10/site-packages/scrapli/decorators.py", line 108, in _multiprocessing_timeout
    return _handle_timeout(
  File "/home/ilya/.local/lib/python3.10/site-packages/scrapli/decorators.py", line 134, in _handle_timeout
    raise ScrapliTimeout(message)
scrapli.exceptions.ScrapliTimeout: timed out sending input to device

2023-02-10 11:17:16,580 - nornir.core.task -    ERROR -      start() - Host 'R2': task 'send_file' failed with traceback:
Traceback (most recent call last):
  File "/home/ilya/.local/lib/python3.10/site-packages/nornir/core/task.py", line 99, in start
    r = self.task(self, **self.params)
  File "/home/ilya/Nornir_Labs/send_from_file.py", line 8, in send_file
    task.run(task=send_commands_from_file, file="commands.txt")
  File "/home/ilya/.local/lib/python3.10/site-packages/nornir/core/task.py", line 174, in run
    raise NornirSubTaskError(task=run_task, result=r)
nornir.core.exceptions.NornirSubTaskError: Subtask: send_commands_from_file (failed)


2023-02-10 11:17:16,584 - nornir.core.task -    ERROR -      start() - Host 'R3': task 'send_commands_from_file' failed with traceback:
Traceback (most recent call last):
  File "/home/ilya/.local/lib/python3.10/site-packages/nornir/core/task.py", line 99, in start
    r = self.task(self, **self.params)
  File "/home/ilya/.local/lib/python3.10/site-packages/nornir_scrapli/tasks/core/send_commands_from_file.py", line 43, in send_commands_from_file
    scrapli_response = scrapli_conn.send_commands_from_file(
  File "/home/ilya/.local/lib/python3.10/site-packages/scrapli/driver/network/sync_driver.py", line 347, in send_commands_from_file
    return super().send_commands_from_file(
  File "/home/ilya/.local/lib/python3.10/site-packages/scrapli/driver/generic/sync_driver.py", line 277, in send_commands_from_file
    return self.send_commands(
  File "/home/ilya/.local/lib/python3.10/site-packages/scrapli/driver/network/sync_driver.py", line 294, in send_commands
    responses = super().send_commands(
  File "/home/ilya/.local/lib/python3.10/site-packages/scrapli/driver/generic/sync_driver.py", line 215, in send_commands
    response = self._send_command(
  File "/home/ilya/.local/lib/python3.10/site-packages/scrapli/decorators.py", line 297, in decorate
    result = wrapped_func(*args, **kwargs)
  File "/home/ilya/.local/lib/python3.10/site-packages/scrapli/driver/generic/sync_driver.py", line 138, in _send_command
    raw_response, processed_response = self.channel.send_input(
  File "/home/ilya/.local/lib/python3.10/site-packages/scrapli/decorators.py", line 216, in decorate
    return _multiprocessing_timeout(
  File "/home/ilya/.local/lib/python3.10/site-packages/scrapli/decorators.py", line 108, in _multiprocessing_timeout
    return _handle_timeout(
  File "/home/ilya/.local/lib/python3.10/site-packages/scrapli/decorators.py", line 134, in _handle_timeout
    raise ScrapliTimeout(message)
scrapli.exceptions.ScrapliTimeout: timed out sending input to device

2023-02-10 11:17:16,585 - nornir.core.task -    ERROR -      start() - Host 'R3': task 'send_file' failed with traceback:
Traceback (most recent call last):
  File "/home/ilya/.local/lib/python3.10/site-packages/nornir/core/task.py", line 99, in start
    r = self.task(self, **self.params)
  File "/home/ilya/Nornir_Labs/send_from_file.py", line 8, in send_file
    task.run(task=send_commands_from_file, file="commands.txt")
  File "/home/ilya/.local/lib/python3.10/site-packages/nornir/core/task.py", line 174, in run
    raise NornirSubTaskError(task=run_task, result=r)
nornir.core.exceptions.NornirSubTaskError: Subtask: send_commands_from_file (failed)


2023-02-10 11:17:16,635 - nornir.core.task -    ERROR -      start() - Host 'R1': task 'send_commands_from_file' failed with traceback:
Traceback (most recent call last):
  File "/home/ilya/.local/lib/python3.10/site-packages/nornir/core/task.py", line 99, in start
    r = self.task(self, **self.params)
  File "/home/ilya/.local/lib/python3.10/site-packages/nornir_scrapli/tasks/core/send_commands_from_file.py", line 43, in send_commands_from_file
    scrapli_response = scrapli_conn.send_commands_from_file(
  File "/home/ilya/.local/lib/python3.10/site-packages/scrapli/driver/network/sync_driver.py", line 347, in send_commands_from_file
    return super().send_commands_from_file(
  File "/home/ilya/.local/lib/python3.10/site-packages/scrapli/driver/generic/sync_driver.py", line 277, in send_commands_from_file
    return self.send_commands(
  File "/home/ilya/.local/lib/python3.10/site-packages/scrapli/driver/network/sync_driver.py", line 294, in send_commands
    responses = super().send_commands(
  File "/home/ilya/.local/lib/python3.10/site-packages/scrapli/driver/generic/sync_driver.py", line 215, in send_commands
    response = self._send_command(
  File "/home/ilya/.local/lib/python3.10/site-packages/scrapli/decorators.py", line 297, in decorate
    result = wrapped_func(*args, **kwargs)
  File "/home/ilya/.local/lib/python3.10/site-packages/scrapli/driver/generic/sync_driver.py", line 138, in _send_command
    raw_response, processed_response = self.channel.send_input(
  File "/home/ilya/.local/lib/python3.10/site-packages/scrapli/decorators.py", line 216, in decorate
    return _multiprocessing_timeout(
  File "/home/ilya/.local/lib/python3.10/site-packages/scrapli/decorators.py", line 108, in _multiprocessing_timeout
    return _handle_timeout(
  File "/home/ilya/.local/lib/python3.10/site-packages/scrapli/decorators.py", line 134, in _handle_timeout
    raise ScrapliTimeout(message)
scrapli.exceptions.ScrapliTimeout: timed out sending input to device

2023-02-10 11:17:16,635 - nornir.core.task -    ERROR -      start() - Host 'R1': task 'send_file' failed with traceback:
Traceback (most recent call last):
  File "/home/ilya/.local/lib/python3.10/site-packages/nornir/core/task.py", line 99, in start
    r = self.task(self, **self.params)
  File "/home/ilya/Nornir_Labs/send_from_file.py", line 8, in send_file
    task.run(task=send_commands_from_file, file="commands.txt")
  File "/home/ilya/.local/lib/python3.10/site-packages/nornir/core/task.py", line 174, in run
    raise NornirSubTaskError(task=run_task, result=r)
nornir.core.exceptions.NornirSubTaskError: Subtask: send_commands_from_file (failed)


2023-02-10 11:18:51,041 -  nornir.core -     INFO -        run() - Running task 'send_file' with args {} on 7 hosts
2023-02-10 11:18:51,041 - nornir.core.task -    ERROR -      start() - Host 'R1': task 'send_file' failed with traceback:
Traceback (most recent call last):
  File "/home/ilya/.local/lib/python3.10/site-packages/nornir/core/task.py", line 99, in start
    r = self.task(self, **self.params)
  File "/home/ilya/Nornir_Labs/send_from_file.py", line 8, in send_file
    task.run(task=send_commands_from_file, file=commands.txt)
NameError: name 'commands' is not defined

2023-02-10 11:18:51,042 - nornir.core.task -    ERROR -      start() - Host 'R3': task 'send_file' failed with traceback:
Traceback (most recent call last):
  File "/home/ilya/.local/lib/python3.10/site-packages/nornir/core/task.py", line 99, in start
    r = self.task(self, **self.params)
  File "/home/ilya/Nornir_Labs/send_from_file.py", line 8, in send_file
    task.run(task=send_commands_from_file, file=commands.txt)
NameError: name 'commands' is not defined

2023-02-10 11:18:51,043 - nornir.core.task -    ERROR -      start() - Host 'R6': task 'send_file' failed with traceback:
Traceback (most recent call last):
  File "/home/ilya/.local/lib/python3.10/site-packages/nornir/core/task.py", line 99, in start
    r = self.task(self, **self.params)
  File "/home/ilya/Nornir_Labs/send_from_file.py", line 8, in send_file
    task.run(task=send_commands_from_file, file=commands.txt)
NameError: name 'commands' is not defined

2023-02-10 11:18:51,043 - nornir.core.task -    ERROR -      start() - Host 'R4': task 'send_file' failed with traceback:
Traceback (most recent call last):
  File "/home/ilya/.local/lib/python3.10/site-packages/nornir/core/task.py", line 99, in start
    r = self.task(self, **self.params)
  File "/home/ilya/Nornir_Labs/send_from_file.py", line 8, in send_file
    task.run(task=send_commands_from_file, file=commands.txt)
NameError: name 'commands' is not defined

2023-02-10 11:18:51,043 - nornir.core.task -    ERROR -      start() - Host 'R2': task 'send_file' failed with traceback:
Traceback (most recent call last):
  File "/home/ilya/.local/lib/python3.10/site-packages/nornir/core/task.py", line 99, in start
    r = self.task(self, **self.params)
  File "/home/ilya/Nornir_Labs/send_from_file.py", line 8, in send_file
    task.run(task=send_commands_from_file, file=commands.txt)
NameError: name 'commands' is not defined

2023-02-10 11:18:51,043 - nornir.core.task -    ERROR -      start() - Host 'R5': task 'send_file' failed with traceback:
Traceback (most recent call last):
  File "/home/ilya/.local/lib/python3.10/site-packages/nornir/core/task.py", line 99, in start
    r = self.task(self, **self.params)
  File "/home/ilya/Nornir_Labs/send_from_file.py", line 8, in send_file
    task.run(task=send_commands_from_file, file=commands.txt)
NameError: name 'commands' is not defined

2023-02-10 11:18:51,043 - nornir.core.task -    ERROR -      start() - Host 'R7': task 'send_file' failed with traceback:
Traceback (most recent call last):
  File "/home/ilya/.local/lib/python3.10/site-packages/nornir/core/task.py", line 99, in start
    r = self.task(self, **self.params)
  File "/home/ilya/Nornir_Labs/send_from_file.py", line 8, in send_file
    task.run(task=send_commands_from_file, file=commands.txt)
NameError: name 'commands' is not defined

2023-02-10 11:23:47,936 -  nornir.core -     INFO -        run() - Running task 'send_file' with args {} on 7 hosts
2023-02-10 11:24:18,554 - nornir.core.task -    ERROR -      start() - Host 'R6': task 'send_commands_from_file' failed with traceback:
Traceback (most recent call last):
  File "/home/ilya/.local/lib/python3.10/site-packages/nornir/core/task.py", line 99, in start
    r = self.task(self, **self.params)
  File "/home/ilya/.local/lib/python3.10/site-packages/nornir_scrapli/tasks/core/send_commands_from_file.py", line 43, in send_commands_from_file
    scrapli_response = scrapli_conn.send_commands_from_file(
  File "/home/ilya/.local/lib/python3.10/site-packages/scrapli/driver/network/sync_driver.py", line 347, in send_commands_from_file
    return super().send_commands_from_file(
  File "/home/ilya/.local/lib/python3.10/site-packages/scrapli/driver/generic/sync_driver.py", line 277, in send_commands_from_file
    return self.send_commands(
  File "/home/ilya/.local/lib/python3.10/site-packages/scrapli/driver/network/sync_driver.py", line 294, in send_commands
    responses = super().send_commands(
  File "/home/ilya/.local/lib/python3.10/site-packages/scrapli/driver/generic/sync_driver.py", line 215, in send_commands
    response = self._send_command(
  File "/home/ilya/.local/lib/python3.10/site-packages/scrapli/decorators.py", line 297, in decorate
    result = wrapped_func(*args, **kwargs)
  File "/home/ilya/.local/lib/python3.10/site-packages/scrapli/driver/generic/sync_driver.py", line 138, in _send_command
    raw_response, processed_response = self.channel.send_input(
  File "/home/ilya/.local/lib/python3.10/site-packages/scrapli/decorators.py", line 216, in decorate
    return _multiprocessing_timeout(
  File "/home/ilya/.local/lib/python3.10/site-packages/scrapli/decorators.py", line 108, in _multiprocessing_timeout
    return _handle_timeout(
  File "/home/ilya/.local/lib/python3.10/site-packages/scrapli/decorators.py", line 134, in _handle_timeout
    raise ScrapliTimeout(message)
scrapli.exceptions.ScrapliTimeout: timed out sending input to device

2023-02-10 11:24:18,555 - nornir.core.task -    ERROR -      start() - Host 'R6': task 'send_file' failed with traceback:
Traceback (most recent call last):
  File "/home/ilya/.local/lib/python3.10/site-packages/nornir/core/task.py", line 99, in start
    r = self.task(self, **self.params)
  File "/home/ilya/Nornir_Labs/send_from_file.py", line 8, in send_file
    task.run(task=send_commands_from_file, file="commands.txt")
  File "/home/ilya/.local/lib/python3.10/site-packages/nornir/core/task.py", line 174, in run
    raise NornirSubTaskError(task=run_task, result=r)
nornir.core.exceptions.NornirSubTaskError: Subtask: send_commands_from_file (failed)


2023-02-10 11:24:18,558 - nornir.core.task -    ERROR -      start() - Host 'R5': task 'send_commands_from_file' failed with traceback:
Traceback (most recent call last):
  File "/home/ilya/.local/lib/python3.10/site-packages/nornir/core/task.py", line 99, in start
    r = self.task(self, **self.params)
  File "/home/ilya/.local/lib/python3.10/site-packages/nornir_scrapli/tasks/core/send_commands_from_file.py", line 43, in send_commands_from_file
    scrapli_response = scrapli_conn.send_commands_from_file(
  File "/home/ilya/.local/lib/python3.10/site-packages/scrapli/driver/network/sync_driver.py", line 347, in send_commands_from_file
    return super().send_commands_from_file(
  File "/home/ilya/.local/lib/python3.10/site-packages/scrapli/driver/generic/sync_driver.py", line 277, in send_commands_from_file
    return self.send_commands(
  File "/home/ilya/.local/lib/python3.10/site-packages/scrapli/driver/network/sync_driver.py", line 294, in send_commands
    responses = super().send_commands(
  File "/home/ilya/.local/lib/python3.10/site-packages/scrapli/driver/generic/sync_driver.py", line 215, in send_commands
    response = self._send_command(
  File "/home/ilya/.local/lib/python3.10/site-packages/scrapli/decorators.py", line 297, in decorate
    result = wrapped_func(*args, **kwargs)
  File "/home/ilya/.local/lib/python3.10/site-packages/scrapli/driver/generic/sync_driver.py", line 138, in _send_command
    raw_response, processed_response = self.channel.send_input(
  File "/home/ilya/.local/lib/python3.10/site-packages/scrapli/decorators.py", line 216, in decorate
    return _multiprocessing_timeout(
  File "/home/ilya/.local/lib/python3.10/site-packages/scrapli/decorators.py", line 108, in _multiprocessing_timeout
    return _handle_timeout(
  File "/home/ilya/.local/lib/python3.10/site-packages/scrapli/decorators.py", line 134, in _handle_timeout
    raise ScrapliTimeout(message)
scrapli.exceptions.ScrapliTimeout: timed out sending input to device

2023-02-10 11:24:18,558 - nornir.core.task -    ERROR -      start() - Host 'R5': task 'send_file' failed with traceback:
Traceback (most recent call last):
  File "/home/ilya/.local/lib/python3.10/site-packages/nornir/core/task.py", line 99, in start
    r = self.task(self, **self.params)
  File "/home/ilya/Nornir_Labs/send_from_file.py", line 8, in send_file
    task.run(task=send_commands_from_file, file="commands.txt")
  File "/home/ilya/.local/lib/python3.10/site-packages/nornir/core/task.py", line 174, in run
    raise NornirSubTaskError(task=run_task, result=r)
nornir.core.exceptions.NornirSubTaskError: Subtask: send_commands_from_file (failed)


2023-02-10 11:24:18,575 - nornir.core.task -    ERROR -      start() - Host 'R4': task 'send_commands_from_file' failed with traceback:
Traceback (most recent call last):
  File "/home/ilya/.local/lib/python3.10/site-packages/nornir/core/task.py", line 99, in start
    r = self.task(self, **self.params)
  File "/home/ilya/.local/lib/python3.10/site-packages/nornir_scrapli/tasks/core/send_commands_from_file.py", line 43, in send_commands_from_file
    scrapli_response = scrapli_conn.send_commands_from_file(
  File "/home/ilya/.local/lib/python3.10/site-packages/scrapli/driver/network/sync_driver.py", line 347, in send_commands_from_file
    return super().send_commands_from_file(
  File "/home/ilya/.local/lib/python3.10/site-packages/scrapli/driver/generic/sync_driver.py", line 277, in send_commands_from_file
    return self.send_commands(
  File "/home/ilya/.local/lib/python3.10/site-packages/scrapli/driver/network/sync_driver.py", line 294, in send_commands
    responses = super().send_commands(
  File "/home/ilya/.local/lib/python3.10/site-packages/scrapli/driver/generic/sync_driver.py", line 215, in send_commands
    response = self._send_command(
  File "/home/ilya/.local/lib/python3.10/site-packages/scrapli/decorators.py", line 297, in decorate
    result = wrapped_func(*args, **kwargs)
  File "/home/ilya/.local/lib/python3.10/site-packages/scrapli/driver/generic/sync_driver.py", line 138, in _send_command
    raw_response, processed_response = self.channel.send_input(
  File "/home/ilya/.local/lib/python3.10/site-packages/scrapli/decorators.py", line 216, in decorate
    return _multiprocessing_timeout(
  File "/home/ilya/.local/lib/python3.10/site-packages/scrapli/decorators.py", line 108, in _multiprocessing_timeout
    return _handle_timeout(
  File "/home/ilya/.local/lib/python3.10/site-packages/scrapli/decorators.py", line 134, in _handle_timeout
    raise ScrapliTimeout(message)
scrapli.exceptions.ScrapliTimeout: timed out sending input to device

2023-02-10 11:24:18,575 - nornir.core.task -    ERROR -      start() - Host 'R4': task 'send_file' failed with traceback:
Traceback (most recent call last):
  File "/home/ilya/.local/lib/python3.10/site-packages/nornir/core/task.py", line 99, in start
    r = self.task(self, **self.params)
  File "/home/ilya/Nornir_Labs/send_from_file.py", line 8, in send_file
    task.run(task=send_commands_from_file, file="commands.txt")
  File "/home/ilya/.local/lib/python3.10/site-packages/nornir/core/task.py", line 174, in run
    raise NornirSubTaskError(task=run_task, result=r)
nornir.core.exceptions.NornirSubTaskError: Subtask: send_commands_from_file (failed)


2023-02-10 11:24:18,591 - nornir.core.task -    ERROR -      start() - Host 'R3': task 'send_commands_from_file' failed with traceback:
Traceback (most recent call last):
  File "/home/ilya/.local/lib/python3.10/site-packages/nornir/core/task.py", line 99, in start
    r = self.task(self, **self.params)
  File "/home/ilya/.local/lib/python3.10/site-packages/nornir_scrapli/tasks/core/send_commands_from_file.py", line 43, in send_commands_from_file
    scrapli_response = scrapli_conn.send_commands_from_file(
  File "/home/ilya/.local/lib/python3.10/site-packages/scrapli/driver/network/sync_driver.py", line 347, in send_commands_from_file
    return super().send_commands_from_file(
  File "/home/ilya/.local/lib/python3.10/site-packages/scrapli/driver/generic/sync_driver.py", line 277, in send_commands_from_file
    return self.send_commands(
  File "/home/ilya/.local/lib/python3.10/site-packages/scrapli/driver/network/sync_driver.py", line 294, in send_commands
    responses = super().send_commands(
  File "/home/ilya/.local/lib/python3.10/site-packages/scrapli/driver/generic/sync_driver.py", line 215, in send_commands
    response = self._send_command(
  File "/home/ilya/.local/lib/python3.10/site-packages/scrapli/decorators.py", line 297, in decorate
    result = wrapped_func(*args, **kwargs)
  File "/home/ilya/.local/lib/python3.10/site-packages/scrapli/driver/generic/sync_driver.py", line 138, in _send_command
    raw_response, processed_response = self.channel.send_input(
  File "/home/ilya/.local/lib/python3.10/site-packages/scrapli/decorators.py", line 216, in decorate
    return _multiprocessing_timeout(
  File "/home/ilya/.local/lib/python3.10/site-packages/scrapli/decorators.py", line 108, in _multiprocessing_timeout
    return _handle_timeout(
  File "/home/ilya/.local/lib/python3.10/site-packages/scrapli/decorators.py", line 134, in _handle_timeout
    raise ScrapliTimeout(message)
scrapli.exceptions.ScrapliTimeout: timed out sending input to device

2023-02-10 11:24:18,592 - nornir.core.task -    ERROR -      start() - Host 'R3': task 'send_file' failed with traceback:
Traceback (most recent call last):
  File "/home/ilya/.local/lib/python3.10/site-packages/nornir/core/task.py", line 99, in start
    r = self.task(self, **self.params)
  File "/home/ilya/Nornir_Labs/send_from_file.py", line 8, in send_file
    task.run(task=send_commands_from_file, file="commands.txt")
  File "/home/ilya/.local/lib/python3.10/site-packages/nornir/core/task.py", line 174, in run
    raise NornirSubTaskError(task=run_task, result=r)
nornir.core.exceptions.NornirSubTaskError: Subtask: send_commands_from_file (failed)


2023-02-10 11:24:18,607 - nornir.core.task -    ERROR -      start() - Host 'R7': task 'send_commands_from_file' failed with traceback:
Traceback (most recent call last):
  File "/home/ilya/.local/lib/python3.10/site-packages/nornir/core/task.py", line 99, in start
    r = self.task(self, **self.params)
  File "/home/ilya/.local/lib/python3.10/site-packages/nornir_scrapli/tasks/core/send_commands_from_file.py", line 43, in send_commands_from_file
    scrapli_response = scrapli_conn.send_commands_from_file(
  File "/home/ilya/.local/lib/python3.10/site-packages/scrapli/driver/network/sync_driver.py", line 347, in send_commands_from_file
    return super().send_commands_from_file(
  File "/home/ilya/.local/lib/python3.10/site-packages/scrapli/driver/generic/sync_driver.py", line 277, in send_commands_from_file
    return self.send_commands(
  File "/home/ilya/.local/lib/python3.10/site-packages/scrapli/driver/network/sync_driver.py", line 294, in send_commands
    responses = super().send_commands(
  File "/home/ilya/.local/lib/python3.10/site-packages/scrapli/driver/generic/sync_driver.py", line 215, in send_commands
    response = self._send_command(
  File "/home/ilya/.local/lib/python3.10/site-packages/scrapli/decorators.py", line 297, in decorate
    result = wrapped_func(*args, **kwargs)
  File "/home/ilya/.local/lib/python3.10/site-packages/scrapli/driver/generic/sync_driver.py", line 138, in _send_command
    raw_response, processed_response = self.channel.send_input(
  File "/home/ilya/.local/lib/python3.10/site-packages/scrapli/decorators.py", line 216, in decorate
    return _multiprocessing_timeout(
  File "/home/ilya/.local/lib/python3.10/site-packages/scrapli/decorators.py", line 108, in _multiprocessing_timeout
    return _handle_timeout(
  File "/home/ilya/.local/lib/python3.10/site-packages/scrapli/decorators.py", line 134, in _handle_timeout
    raise ScrapliTimeout(message)
scrapli.exceptions.ScrapliTimeout: timed out sending input to device

2023-02-10 11:24:18,608 - nornir.core.task -    ERROR -      start() - Host 'R7': task 'send_file' failed with traceback:
Traceback (most recent call last):
  File "/home/ilya/.local/lib/python3.10/site-packages/nornir/core/task.py", line 99, in start
    r = self.task(self, **self.params)
  File "/home/ilya/Nornir_Labs/send_from_file.py", line 8, in send_file
    task.run(task=send_commands_from_file, file="commands.txt")
  File "/home/ilya/.local/lib/python3.10/site-packages/nornir/core/task.py", line 174, in run
    raise NornirSubTaskError(task=run_task, result=r)
nornir.core.exceptions.NornirSubTaskError: Subtask: send_commands_from_file (failed)


2023-02-10 11:24:18,641 - nornir.core.task -    ERROR -      start() - Host 'R1': task 'send_commands_from_file' failed with traceback:
Traceback (most recent call last):
  File "/home/ilya/.local/lib/python3.10/site-packages/nornir/core/task.py", line 99, in start
    r = self.task(self, **self.params)
  File "/home/ilya/.local/lib/python3.10/site-packages/nornir_scrapli/tasks/core/send_commands_from_file.py", line 43, in send_commands_from_file
    scrapli_response = scrapli_conn.send_commands_from_file(
  File "/home/ilya/.local/lib/python3.10/site-packages/scrapli/driver/network/sync_driver.py", line 347, in send_commands_from_file
    return super().send_commands_from_file(
  File "/home/ilya/.local/lib/python3.10/site-packages/scrapli/driver/generic/sync_driver.py", line 277, in send_commands_from_file
    return self.send_commands(
  File "/home/ilya/.local/lib/python3.10/site-packages/scrapli/driver/network/sync_driver.py", line 294, in send_commands
    responses = super().send_commands(
  File "/home/ilya/.local/lib/python3.10/site-packages/scrapli/driver/generic/sync_driver.py", line 215, in send_commands
    response = self._send_command(
  File "/home/ilya/.local/lib/python3.10/site-packages/scrapli/decorators.py", line 297, in decorate
    result = wrapped_func(*args, **kwargs)
  File "/home/ilya/.local/lib/python3.10/site-packages/scrapli/driver/generic/sync_driver.py", line 138, in _send_command
    raw_response, processed_response = self.channel.send_input(
  File "/home/ilya/.local/lib/python3.10/site-packages/scrapli/decorators.py", line 216, in decorate
    return _multiprocessing_timeout(
  File "/home/ilya/.local/lib/python3.10/site-packages/scrapli/decorators.py", line 108, in _multiprocessing_timeout
    return _handle_timeout(
  File "/home/ilya/.local/lib/python3.10/site-packages/scrapli/decorators.py", line 134, in _handle_timeout
    raise ScrapliTimeout(message)
scrapli.exceptions.ScrapliTimeout: timed out sending input to device

2023-02-10 11:24:18,641 - nornir.core.task -    ERROR -      start() - Host 'R1': task 'send_file' failed with traceback:
Traceback (most recent call last):
  File "/home/ilya/.local/lib/python3.10/site-packages/nornir/core/task.py", line 99, in start
    r = self.task(self, **self.params)
  File "/home/ilya/Nornir_Labs/send_from_file.py", line 8, in send_file
    task.run(task=send_commands_from_file, file="commands.txt")
  File "/home/ilya/.local/lib/python3.10/site-packages/nornir/core/task.py", line 174, in run
    raise NornirSubTaskError(task=run_task, result=r)
nornir.core.exceptions.NornirSubTaskError: Subtask: send_commands_from_file (failed)


2023-02-10 11:24:18,649 - nornir.core.task -    ERROR -      start() - Host 'R2': task 'send_commands_from_file' failed with traceback:
Traceback (most recent call last):
  File "/home/ilya/.local/lib/python3.10/site-packages/nornir/core/task.py", line 99, in start
    r = self.task(self, **self.params)
  File "/home/ilya/.local/lib/python3.10/site-packages/nornir_scrapli/tasks/core/send_commands_from_file.py", line 43, in send_commands_from_file
    scrapli_response = scrapli_conn.send_commands_from_file(
  File "/home/ilya/.local/lib/python3.10/site-packages/scrapli/driver/network/sync_driver.py", line 347, in send_commands_from_file
    return super().send_commands_from_file(
  File "/home/ilya/.local/lib/python3.10/site-packages/scrapli/driver/generic/sync_driver.py", line 277, in send_commands_from_file
    return self.send_commands(
  File "/home/ilya/.local/lib/python3.10/site-packages/scrapli/driver/network/sync_driver.py", line 294, in send_commands
    responses = super().send_commands(
  File "/home/ilya/.local/lib/python3.10/site-packages/scrapli/driver/generic/sync_driver.py", line 215, in send_commands
    response = self._send_command(
  File "/home/ilya/.local/lib/python3.10/site-packages/scrapli/decorators.py", line 297, in decorate
    result = wrapped_func(*args, **kwargs)
  File "/home/ilya/.local/lib/python3.10/site-packages/scrapli/driver/generic/sync_driver.py", line 138, in _send_command
    raw_response, processed_response = self.channel.send_input(
  File "/home/ilya/.local/lib/python3.10/site-packages/scrapli/decorators.py", line 216, in decorate
    return _multiprocessing_timeout(
  File "/home/ilya/.local/lib/python3.10/site-packages/scrapli/decorators.py", line 108, in _multiprocessing_timeout
    return _handle_timeout(
  File "/home/ilya/.local/lib/python3.10/site-packages/scrapli/decorators.py", line 134, in _handle_timeout
    raise ScrapliTimeout(message)
scrapli.exceptions.ScrapliTimeout: timed out sending input to device

2023-02-10 11:24:18,649 - nornir.core.task -    ERROR -      start() - Host 'R2': task 'send_file' failed with traceback:
Traceback (most recent call last):
  File "/home/ilya/.local/lib/python3.10/site-packages/nornir/core/task.py", line 99, in start
    r = self.task(self, **self.params)
  File "/home/ilya/Nornir_Labs/send_from_file.py", line 8, in send_file
    task.run(task=send_commands_from_file, file="commands.txt")
  File "/home/ilya/.local/lib/python3.10/site-packages/nornir/core/task.py", line 174, in run
    raise NornirSubTaskError(task=run_task, result=r)
nornir.core.exceptions.NornirSubTaskError: Subtask: send_commands_from_file (failed)


2023-02-10 11:25:27,045 -  nornir.core -     INFO -        run() - Running task 'send_file' with args {} on 7 hosts
2023-02-10 11:25:57,662 - nornir.core.task -    ERROR -      start() - Host 'R5': task 'send_commands_from_file' failed with traceback:
Traceback (most recent call last):
  File "/home/ilya/.local/lib/python3.10/site-packages/nornir/core/task.py", line 99, in start
    r = self.task(self, **self.params)
  File "/home/ilya/.local/lib/python3.10/site-packages/nornir_scrapli/tasks/core/send_commands_from_file.py", line 43, in send_commands_from_file
    scrapli_response = scrapli_conn.send_commands_from_file(
  File "/home/ilya/.local/lib/python3.10/site-packages/scrapli/driver/network/sync_driver.py", line 347, in send_commands_from_file
    return super().send_commands_from_file(
  File "/home/ilya/.local/lib/python3.10/site-packages/scrapli/driver/generic/sync_driver.py", line 277, in send_commands_from_file
    return self.send_commands(
  File "/home/ilya/.local/lib/python3.10/site-packages/scrapli/driver/network/sync_driver.py", line 294, in send_commands
    responses = super().send_commands(
  File "/home/ilya/.local/lib/python3.10/site-packages/scrapli/driver/generic/sync_driver.py", line 215, in send_commands
    response = self._send_command(
  File "/home/ilya/.local/lib/python3.10/site-packages/scrapli/decorators.py", line 297, in decorate
    result = wrapped_func(*args, **kwargs)
  File "/home/ilya/.local/lib/python3.10/site-packages/scrapli/driver/generic/sync_driver.py", line 138, in _send_command
    raw_response, processed_response = self.channel.send_input(
  File "/home/ilya/.local/lib/python3.10/site-packages/scrapli/decorators.py", line 216, in decorate
    return _multiprocessing_timeout(
  File "/home/ilya/.local/lib/python3.10/site-packages/scrapli/decorators.py", line 108, in _multiprocessing_timeout
    return _handle_timeout(
  File "/home/ilya/.local/lib/python3.10/site-packages/scrapli/decorators.py", line 134, in _handle_timeout
    raise ScrapliTimeout(message)
scrapli.exceptions.ScrapliTimeout: timed out sending input to device

2023-02-10 11:25:57,662 - nornir.core.task -    ERROR -      start() - Host 'R5': task 'send_file' failed with traceback:
Traceback (most recent call last):
  File "/home/ilya/.local/lib/python3.10/site-packages/nornir/core/task.py", line 99, in start
    r = self.task(self, **self.params)
  File "/home/ilya/Nornir_Labs/send_from_file.py", line 8, in send_file
    task.run(task=send_commands_from_file, file="commands.txt")
  File "/home/ilya/.local/lib/python3.10/site-packages/nornir/core/task.py", line 174, in run
    raise NornirSubTaskError(task=run_task, result=r)
nornir.core.exceptions.NornirSubTaskError: Subtask: send_commands_from_file (failed)


2023-02-10 11:25:57,665 - nornir.core.task -    ERROR -      start() - Host 'R7': task 'send_commands_from_file' failed with traceback:
Traceback (most recent call last):
  File "/home/ilya/.local/lib/python3.10/site-packages/nornir/core/task.py", line 99, in start
    r = self.task(self, **self.params)
  File "/home/ilya/.local/lib/python3.10/site-packages/nornir_scrapli/tasks/core/send_commands_from_file.py", line 43, in send_commands_from_file
    scrapli_response = scrapli_conn.send_commands_from_file(
  File "/home/ilya/.local/lib/python3.10/site-packages/scrapli/driver/network/sync_driver.py", line 347, in send_commands_from_file
    return super().send_commands_from_file(
  File "/home/ilya/.local/lib/python3.10/site-packages/scrapli/driver/generic/sync_driver.py", line 277, in send_commands_from_file
    return self.send_commands(
  File "/home/ilya/.local/lib/python3.10/site-packages/scrapli/driver/network/sync_driver.py", line 294, in send_commands
    responses = super().send_commands(
  File "/home/ilya/.local/lib/python3.10/site-packages/scrapli/driver/generic/sync_driver.py", line 215, in send_commands
    response = self._send_command(
  File "/home/ilya/.local/lib/python3.10/site-packages/scrapli/decorators.py", line 297, in decorate
    result = wrapped_func(*args, **kwargs)
  File "/home/ilya/.local/lib/python3.10/site-packages/scrapli/driver/generic/sync_driver.py", line 138, in _send_command
    raw_response, processed_response = self.channel.send_input(
  File "/home/ilya/.local/lib/python3.10/site-packages/scrapli/decorators.py", line 216, in decorate
    return _multiprocessing_timeout(
  File "/home/ilya/.local/lib/python3.10/site-packages/scrapli/decorators.py", line 108, in _multiprocessing_timeout
    return _handle_timeout(
  File "/home/ilya/.local/lib/python3.10/site-packages/scrapli/decorators.py", line 134, in _handle_timeout
    raise ScrapliTimeout(message)
scrapli.exceptions.ScrapliTimeout: timed out sending input to device

2023-02-10 11:25:57,665 - nornir.core.task -    ERROR -      start() - Host 'R7': task 'send_file' failed with traceback:
Traceback (most recent call last):
  File "/home/ilya/.local/lib/python3.10/site-packages/nornir/core/task.py", line 99, in start
    r = self.task(self, **self.params)
  File "/home/ilya/Nornir_Labs/send_from_file.py", line 8, in send_file
    task.run(task=send_commands_from_file, file="commands.txt")
  File "/home/ilya/.local/lib/python3.10/site-packages/nornir/core/task.py", line 174, in run
    raise NornirSubTaskError(task=run_task, result=r)
nornir.core.exceptions.NornirSubTaskError: Subtask: send_commands_from_file (failed)


2023-02-10 11:25:57,667 - nornir.core.task -    ERROR -      start() - Host 'R4': task 'send_commands_from_file' failed with traceback:
Traceback (most recent call last):
  File "/home/ilya/.local/lib/python3.10/site-packages/nornir/core/task.py", line 99, in start
    r = self.task(self, **self.params)
  File "/home/ilya/.local/lib/python3.10/site-packages/nornir_scrapli/tasks/core/send_commands_from_file.py", line 43, in send_commands_from_file
    scrapli_response = scrapli_conn.send_commands_from_file(
  File "/home/ilya/.local/lib/python3.10/site-packages/scrapli/driver/network/sync_driver.py", line 347, in send_commands_from_file
    return super().send_commands_from_file(
  File "/home/ilya/.local/lib/python3.10/site-packages/scrapli/driver/generic/sync_driver.py", line 277, in send_commands_from_file
    return self.send_commands(
  File "/home/ilya/.local/lib/python3.10/site-packages/scrapli/driver/network/sync_driver.py", line 294, in send_commands
    responses = super().send_commands(
  File "/home/ilya/.local/lib/python3.10/site-packages/scrapli/driver/generic/sync_driver.py", line 215, in send_commands
    response = self._send_command(
  File "/home/ilya/.local/lib/python3.10/site-packages/scrapli/decorators.py", line 297, in decorate
    result = wrapped_func(*args, **kwargs)
  File "/home/ilya/.local/lib/python3.10/site-packages/scrapli/driver/generic/sync_driver.py", line 138, in _send_command
    raw_response, processed_response = self.channel.send_input(
  File "/home/ilya/.local/lib/python3.10/site-packages/scrapli/decorators.py", line 216, in decorate
    return _multiprocessing_timeout(
  File "/home/ilya/.local/lib/python3.10/site-packages/scrapli/decorators.py", line 108, in _multiprocessing_timeout
    return _handle_timeout(
  File "/home/ilya/.local/lib/python3.10/site-packages/scrapli/decorators.py", line 134, in _handle_timeout
    raise ScrapliTimeout(message)
scrapli.exceptions.ScrapliTimeout: timed out sending input to device

2023-02-10 11:25:57,667 - nornir.core.task -    ERROR -      start() - Host 'R4': task 'send_file' failed with traceback:
Traceback (most recent call last):
  File "/home/ilya/.local/lib/python3.10/site-packages/nornir/core/task.py", line 99, in start
    r = self.task(self, **self.params)
  File "/home/ilya/Nornir_Labs/send_from_file.py", line 8, in send_file
    task.run(task=send_commands_from_file, file="commands.txt")
  File "/home/ilya/.local/lib/python3.10/site-packages/nornir/core/task.py", line 174, in run
    raise NornirSubTaskError(task=run_task, result=r)
nornir.core.exceptions.NornirSubTaskError: Subtask: send_commands_from_file (failed)


2023-02-10 11:25:57,690 - nornir.core.task -    ERROR -      start() - Host 'R6': task 'send_commands_from_file' failed with traceback:
Traceback (most recent call last):
  File "/home/ilya/.local/lib/python3.10/site-packages/nornir/core/task.py", line 99, in start
    r = self.task(self, **self.params)
  File "/home/ilya/.local/lib/python3.10/site-packages/nornir_scrapli/tasks/core/send_commands_from_file.py", line 43, in send_commands_from_file
    scrapli_response = scrapli_conn.send_commands_from_file(
  File "/home/ilya/.local/lib/python3.10/site-packages/scrapli/driver/network/sync_driver.py", line 347, in send_commands_from_file
    return super().send_commands_from_file(
  File "/home/ilya/.local/lib/python3.10/site-packages/scrapli/driver/generic/sync_driver.py", line 277, in send_commands_from_file
    return self.send_commands(
  File "/home/ilya/.local/lib/python3.10/site-packages/scrapli/driver/network/sync_driver.py", line 294, in send_commands
    responses = super().send_commands(
  File "/home/ilya/.local/lib/python3.10/site-packages/scrapli/driver/generic/sync_driver.py", line 215, in send_commands
    response = self._send_command(
  File "/home/ilya/.local/lib/python3.10/site-packages/scrapli/decorators.py", line 297, in decorate
    result = wrapped_func(*args, **kwargs)
  File "/home/ilya/.local/lib/python3.10/site-packages/scrapli/driver/generic/sync_driver.py", line 138, in _send_command
    raw_response, processed_response = self.channel.send_input(
  File "/home/ilya/.local/lib/python3.10/site-packages/scrapli/decorators.py", line 216, in decorate
    return _multiprocessing_timeout(
  File "/home/ilya/.local/lib/python3.10/site-packages/scrapli/decorators.py", line 108, in _multiprocessing_timeout
    return _handle_timeout(
  File "/home/ilya/.local/lib/python3.10/site-packages/scrapli/decorators.py", line 134, in _handle_timeout
    raise ScrapliTimeout(message)
scrapli.exceptions.ScrapliTimeout: timed out sending input to device

2023-02-10 11:25:57,690 - nornir.core.task -    ERROR -      start() - Host 'R6': task 'send_file' failed with traceback:
Traceback (most recent call last):
  File "/home/ilya/.local/lib/python3.10/site-packages/nornir/core/task.py", line 99, in start
    r = self.task(self, **self.params)
  File "/home/ilya/Nornir_Labs/send_from_file.py", line 8, in send_file
    task.run(task=send_commands_from_file, file="commands.txt")
  File "/home/ilya/.local/lib/python3.10/site-packages/nornir/core/task.py", line 174, in run
    raise NornirSubTaskError(task=run_task, result=r)
nornir.core.exceptions.NornirSubTaskError: Subtask: send_commands_from_file (failed)


2023-02-10 11:25:57,700 - nornir.core.task -    ERROR -      start() - Host 'R3': task 'send_commands_from_file' failed with traceback:
Traceback (most recent call last):
  File "/home/ilya/.local/lib/python3.10/site-packages/nornir/core/task.py", line 99, in start
    r = self.task(self, **self.params)
  File "/home/ilya/.local/lib/python3.10/site-packages/nornir_scrapli/tasks/core/send_commands_from_file.py", line 43, in send_commands_from_file
    scrapli_response = scrapli_conn.send_commands_from_file(
  File "/home/ilya/.local/lib/python3.10/site-packages/scrapli/driver/network/sync_driver.py", line 347, in send_commands_from_file
    return super().send_commands_from_file(
  File "/home/ilya/.local/lib/python3.10/site-packages/scrapli/driver/generic/sync_driver.py", line 277, in send_commands_from_file
    return self.send_commands(
  File "/home/ilya/.local/lib/python3.10/site-packages/scrapli/driver/network/sync_driver.py", line 294, in send_commands
    responses = super().send_commands(
  File "/home/ilya/.local/lib/python3.10/site-packages/scrapli/driver/generic/sync_driver.py", line 215, in send_commands
    response = self._send_command(
  File "/home/ilya/.local/lib/python3.10/site-packages/scrapli/decorators.py", line 297, in decorate
    result = wrapped_func(*args, **kwargs)
  File "/home/ilya/.local/lib/python3.10/site-packages/scrapli/driver/generic/sync_driver.py", line 138, in _send_command
    raw_response, processed_response = self.channel.send_input(
  File "/home/ilya/.local/lib/python3.10/site-packages/scrapli/decorators.py", line 216, in decorate
    return _multiprocessing_timeout(
  File "/home/ilya/.local/lib/python3.10/site-packages/scrapli/decorators.py", line 108, in _multiprocessing_timeout
    return _handle_timeout(
  File "/home/ilya/.local/lib/python3.10/site-packages/scrapli/decorators.py", line 134, in _handle_timeout
    raise ScrapliTimeout(message)
scrapli.exceptions.ScrapliTimeout: timed out sending input to device

2023-02-10 11:25:57,700 - nornir.core.task -    ERROR -      start() - Host 'R3': task 'send_file' failed with traceback:
Traceback (most recent call last):
  File "/home/ilya/.local/lib/python3.10/site-packages/nornir/core/task.py", line 99, in start
    r = self.task(self, **self.params)
  File "/home/ilya/Nornir_Labs/send_from_file.py", line 8, in send_file
    task.run(task=send_commands_from_file, file="commands.txt")
  File "/home/ilya/.local/lib/python3.10/site-packages/nornir/core/task.py", line 174, in run
    raise NornirSubTaskError(task=run_task, result=r)
nornir.core.exceptions.NornirSubTaskError: Subtask: send_commands_from_file (failed)


2023-02-10 11:25:57,727 - nornir.core.task -    ERROR -      start() - Host 'R2': task 'send_commands_from_file' failed with traceback:
Traceback (most recent call last):
  File "/home/ilya/.local/lib/python3.10/site-packages/nornir/core/task.py", line 99, in start
    r = self.task(self, **self.params)
  File "/home/ilya/.local/lib/python3.10/site-packages/nornir_scrapli/tasks/core/send_commands_from_file.py", line 43, in send_commands_from_file
    scrapli_response = scrapli_conn.send_commands_from_file(
  File "/home/ilya/.local/lib/python3.10/site-packages/scrapli/driver/network/sync_driver.py", line 347, in send_commands_from_file
    return super().send_commands_from_file(
  File "/home/ilya/.local/lib/python3.10/site-packages/scrapli/driver/generic/sync_driver.py", line 277, in send_commands_from_file
    return self.send_commands(
  File "/home/ilya/.local/lib/python3.10/site-packages/scrapli/driver/network/sync_driver.py", line 294, in send_commands
    responses = super().send_commands(
  File "/home/ilya/.local/lib/python3.10/site-packages/scrapli/driver/generic/sync_driver.py", line 215, in send_commands
    response = self._send_command(
  File "/home/ilya/.local/lib/python3.10/site-packages/scrapli/decorators.py", line 297, in decorate
    result = wrapped_func(*args, **kwargs)
  File "/home/ilya/.local/lib/python3.10/site-packages/scrapli/driver/generic/sync_driver.py", line 138, in _send_command
    raw_response, processed_response = self.channel.send_input(
  File "/home/ilya/.local/lib/python3.10/site-packages/scrapli/decorators.py", line 216, in decorate
    return _multiprocessing_timeout(
  File "/home/ilya/.local/lib/python3.10/site-packages/scrapli/decorators.py", line 108, in _multiprocessing_timeout
    return _handle_timeout(
  File "/home/ilya/.local/lib/python3.10/site-packages/scrapli/decorators.py", line 134, in _handle_timeout
    raise ScrapliTimeout(message)
scrapli.exceptions.ScrapliTimeout: timed out sending input to device

2023-02-10 11:25:57,727 - nornir.core.task -    ERROR -      start() - Host 'R2': task 'send_file' failed with traceback:
Traceback (most recent call last):
  File "/home/ilya/.local/lib/python3.10/site-packages/nornir/core/task.py", line 99, in start
    r = self.task(self, **self.params)
  File "/home/ilya/Nornir_Labs/send_from_file.py", line 8, in send_file
    task.run(task=send_commands_from_file, file="commands.txt")
  File "/home/ilya/.local/lib/python3.10/site-packages/nornir/core/task.py", line 174, in run
    raise NornirSubTaskError(task=run_task, result=r)
nornir.core.exceptions.NornirSubTaskError: Subtask: send_commands_from_file (failed)


2023-02-10 11:25:57,736 - nornir.core.task -    ERROR -      start() - Host 'R1': task 'send_commands_from_file' failed with traceback:
Traceback (most recent call last):
  File "/home/ilya/.local/lib/python3.10/site-packages/nornir/core/task.py", line 99, in start
    r = self.task(self, **self.params)
  File "/home/ilya/.local/lib/python3.10/site-packages/nornir_scrapli/tasks/core/send_commands_from_file.py", line 43, in send_commands_from_file
    scrapli_response = scrapli_conn.send_commands_from_file(
  File "/home/ilya/.local/lib/python3.10/site-packages/scrapli/driver/network/sync_driver.py", line 347, in send_commands_from_file
    return super().send_commands_from_file(
  File "/home/ilya/.local/lib/python3.10/site-packages/scrapli/driver/generic/sync_driver.py", line 277, in send_commands_from_file
    return self.send_commands(
  File "/home/ilya/.local/lib/python3.10/site-packages/scrapli/driver/network/sync_driver.py", line 294, in send_commands
    responses = super().send_commands(
  File "/home/ilya/.local/lib/python3.10/site-packages/scrapli/driver/generic/sync_driver.py", line 215, in send_commands
    response = self._send_command(
  File "/home/ilya/.local/lib/python3.10/site-packages/scrapli/decorators.py", line 297, in decorate
    result = wrapped_func(*args, **kwargs)
  File "/home/ilya/.local/lib/python3.10/site-packages/scrapli/driver/generic/sync_driver.py", line 138, in _send_command
    raw_response, processed_response = self.channel.send_input(
  File "/home/ilya/.local/lib/python3.10/site-packages/scrapli/decorators.py", line 216, in decorate
    return _multiprocessing_timeout(
  File "/home/ilya/.local/lib/python3.10/site-packages/scrapli/decorators.py", line 108, in _multiprocessing_timeout
    return _handle_timeout(
  File "/home/ilya/.local/lib/python3.10/site-packages/scrapli/decorators.py", line 134, in _handle_timeout
    raise ScrapliTimeout(message)
scrapli.exceptions.ScrapliTimeout: timed out sending input to device

2023-02-10 11:25:57,736 - nornir.core.task -    ERROR -      start() - Host 'R1': task 'send_file' failed with traceback:
Traceback (most recent call last):
  File "/home/ilya/.local/lib/python3.10/site-packages/nornir/core/task.py", line 99, in start
    r = self.task(self, **self.params)
  File "/home/ilya/Nornir_Labs/send_from_file.py", line 8, in send_file
    task.run(task=send_commands_from_file, file="commands.txt")
  File "/home/ilya/.local/lib/python3.10/site-packages/nornir/core/task.py", line 174, in run
    raise NornirSubTaskError(task=run_task, result=r)
nornir.core.exceptions.NornirSubTaskError: Subtask: send_commands_from_file (failed)


2023-02-10 11:27:09,577 -  nornir.core -     INFO -        run() - Running task 'show_command_test' with args {} on 7 hosts
2023-02-10 11:29:06,355 -  nornir.core -     INFO -        run() - Running task 'send_file' with args {} on 7 hosts
2023-02-10 11:29:31,021 -  nornir.core -     INFO -        run() - Running task 'send_file' with args {} on 7 hosts
2023-02-10 11:30:29,448 -  nornir.core -     INFO -        run() - Running task 'send_file' with args {} on 7 hosts
2023-02-10 11:31:00,111 - nornir.core.task -    ERROR -      start() - Host 'R7': task 'send_commands_from_file' failed with traceback:
Traceback (most recent call last):
  File "/home/ilya/.local/lib/python3.10/site-packages/nornir/core/task.py", line 99, in start
    r = self.task(self, **self.params)
  File "/home/ilya/.local/lib/python3.10/site-packages/nornir_scrapli/tasks/core/send_commands_from_file.py", line 43, in send_commands_from_file
    scrapli_response = scrapli_conn.send_commands_from_file(
  File "/home/ilya/.local/lib/python3.10/site-packages/scrapli/driver/network/sync_driver.py", line 347, in send_commands_from_file
    return super().send_commands_from_file(
  File "/home/ilya/.local/lib/python3.10/site-packages/scrapli/driver/generic/sync_driver.py", line 277, in send_commands_from_file
    return self.send_commands(
  File "/home/ilya/.local/lib/python3.10/site-packages/scrapli/driver/network/sync_driver.py", line 294, in send_commands
    responses = super().send_commands(
  File "/home/ilya/.local/lib/python3.10/site-packages/scrapli/driver/generic/sync_driver.py", line 215, in send_commands
    response = self._send_command(
  File "/home/ilya/.local/lib/python3.10/site-packages/scrapli/decorators.py", line 297, in decorate
    result = wrapped_func(*args, **kwargs)
  File "/home/ilya/.local/lib/python3.10/site-packages/scrapli/driver/generic/sync_driver.py", line 138, in _send_command
    raw_response, processed_response = self.channel.send_input(
  File "/home/ilya/.local/lib/python3.10/site-packages/scrapli/decorators.py", line 216, in decorate
    return _multiprocessing_timeout(
  File "/home/ilya/.local/lib/python3.10/site-packages/scrapli/decorators.py", line 108, in _multiprocessing_timeout
    return _handle_timeout(
  File "/home/ilya/.local/lib/python3.10/site-packages/scrapli/decorators.py", line 134, in _handle_timeout
    raise ScrapliTimeout(message)
scrapli.exceptions.ScrapliTimeout: timed out sending input to device

2023-02-10 11:31:00,112 - nornir.core.task -    ERROR -      start() - Host 'R7': task 'send_file' failed with traceback:
Traceback (most recent call last):
  File "/home/ilya/.local/lib/python3.10/site-packages/nornir/core/task.py", line 99, in start
    r = self.task(self, **self.params)
  File "/home/ilya/Nornir_Labs/send_from_file.py", line 8, in send_file
    task.run(task=send_commands_from_file, file="commands.txt")
  File "/home/ilya/.local/lib/python3.10/site-packages/nornir/core/task.py", line 174, in run
    raise NornirSubTaskError(task=run_task, result=r)
nornir.core.exceptions.NornirSubTaskError: Subtask: send_commands_from_file (failed)


2023-02-10 11:31:00,113 - nornir.core.task -    ERROR -      start() - Host 'R6': task 'send_commands_from_file' failed with traceback:
Traceback (most recent call last):
  File "/home/ilya/.local/lib/python3.10/site-packages/nornir/core/task.py", line 99, in start
    r = self.task(self, **self.params)
  File "/home/ilya/.local/lib/python3.10/site-packages/nornir_scrapli/tasks/core/send_commands_from_file.py", line 43, in send_commands_from_file
    scrapli_response = scrapli_conn.send_commands_from_file(
  File "/home/ilya/.local/lib/python3.10/site-packages/scrapli/driver/network/sync_driver.py", line 347, in send_commands_from_file
    return super().send_commands_from_file(
  File "/home/ilya/.local/lib/python3.10/site-packages/scrapli/driver/generic/sync_driver.py", line 277, in send_commands_from_file
    return self.send_commands(
  File "/home/ilya/.local/lib/python3.10/site-packages/scrapli/driver/network/sync_driver.py", line 294, in send_commands
    responses = super().send_commands(
  File "/home/ilya/.local/lib/python3.10/site-packages/scrapli/driver/generic/sync_driver.py", line 215, in send_commands
    response = self._send_command(
  File "/home/ilya/.local/lib/python3.10/site-packages/scrapli/decorators.py", line 297, in decorate
    result = wrapped_func(*args, **kwargs)
  File "/home/ilya/.local/lib/python3.10/site-packages/scrapli/driver/generic/sync_driver.py", line 138, in _send_command
    raw_response, processed_response = self.channel.send_input(
  File "/home/ilya/.local/lib/python3.10/site-packages/scrapli/decorators.py", line 216, in decorate
    return _multiprocessing_timeout(
  File "/home/ilya/.local/lib/python3.10/site-packages/scrapli/decorators.py", line 108, in _multiprocessing_timeout
    return _handle_timeout(
  File "/home/ilya/.local/lib/python3.10/site-packages/scrapli/decorators.py", line 134, in _handle_timeout
    raise ScrapliTimeout(message)
scrapli.exceptions.ScrapliTimeout: timed out sending input to device

2023-02-10 11:31:00,113 - nornir.core.task -    ERROR -      start() - Host 'R6': task 'send_file' failed with traceback:
Traceback (most recent call last):
  File "/home/ilya/.local/lib/python3.10/site-packages/nornir/core/task.py", line 99, in start
    r = self.task(self, **self.params)
  File "/home/ilya/Nornir_Labs/send_from_file.py", line 8, in send_file
    task.run(task=send_commands_from_file, file="commands.txt")
  File "/home/ilya/.local/lib/python3.10/site-packages/nornir/core/task.py", line 174, in run
    raise NornirSubTaskError(task=run_task, result=r)
nornir.core.exceptions.NornirSubTaskError: Subtask: send_commands_from_file (failed)


2023-02-10 11:31:00,134 - nornir.core.task -    ERROR -      start() - Host 'R4': task 'send_commands_from_file' failed with traceback:
Traceback (most recent call last):
  File "/home/ilya/.local/lib/python3.10/site-packages/nornir/core/task.py", line 99, in start
    r = self.task(self, **self.params)
  File "/home/ilya/.local/lib/python3.10/site-packages/nornir_scrapli/tasks/core/send_commands_from_file.py", line 43, in send_commands_from_file
    scrapli_response = scrapli_conn.send_commands_from_file(
  File "/home/ilya/.local/lib/python3.10/site-packages/scrapli/driver/network/sync_driver.py", line 347, in send_commands_from_file
    return super().send_commands_from_file(
  File "/home/ilya/.local/lib/python3.10/site-packages/scrapli/driver/generic/sync_driver.py", line 277, in send_commands_from_file
    return self.send_commands(
  File "/home/ilya/.local/lib/python3.10/site-packages/scrapli/driver/network/sync_driver.py", line 294, in send_commands
    responses = super().send_commands(
  File "/home/ilya/.local/lib/python3.10/site-packages/scrapli/driver/generic/sync_driver.py", line 215, in send_commands
    response = self._send_command(
  File "/home/ilya/.local/lib/python3.10/site-packages/scrapli/decorators.py", line 297, in decorate
    result = wrapped_func(*args, **kwargs)
  File "/home/ilya/.local/lib/python3.10/site-packages/scrapli/driver/generic/sync_driver.py", line 138, in _send_command
    raw_response, processed_response = self.channel.send_input(
  File "/home/ilya/.local/lib/python3.10/site-packages/scrapli/decorators.py", line 216, in decorate
    return _multiprocessing_timeout(
  File "/home/ilya/.local/lib/python3.10/site-packages/scrapli/decorators.py", line 108, in _multiprocessing_timeout
    return _handle_timeout(
  File "/home/ilya/.local/lib/python3.10/site-packages/scrapli/decorators.py", line 134, in _handle_timeout
    raise ScrapliTimeout(message)
scrapli.exceptions.ScrapliTimeout: timed out sending input to device

2023-02-10 11:31:00,134 - nornir.core.task -    ERROR -      start() - Host 'R4': task 'send_file' failed with traceback:
Traceback (most recent call last):
  File "/home/ilya/.local/lib/python3.10/site-packages/nornir/core/task.py", line 99, in start
    r = self.task(self, **self.params)
  File "/home/ilya/Nornir_Labs/send_from_file.py", line 8, in send_file
    task.run(task=send_commands_from_file, file="commands.txt")
  File "/home/ilya/.local/lib/python3.10/site-packages/nornir/core/task.py", line 174, in run
    raise NornirSubTaskError(task=run_task, result=r)
nornir.core.exceptions.NornirSubTaskError: Subtask: send_commands_from_file (failed)


2023-02-10 11:31:00,146 - nornir.core.task -    ERROR -      start() - Host 'R2': task 'send_commands_from_file' failed with traceback:
Traceback (most recent call last):
  File "/home/ilya/.local/lib/python3.10/site-packages/nornir/core/task.py", line 99, in start
    r = self.task(self, **self.params)
  File "/home/ilya/.local/lib/python3.10/site-packages/nornir_scrapli/tasks/core/send_commands_from_file.py", line 43, in send_commands_from_file
    scrapli_response = scrapli_conn.send_commands_from_file(
  File "/home/ilya/.local/lib/python3.10/site-packages/scrapli/driver/network/sync_driver.py", line 347, in send_commands_from_file
    return super().send_commands_from_file(
  File "/home/ilya/.local/lib/python3.10/site-packages/scrapli/driver/generic/sync_driver.py", line 277, in send_commands_from_file
    return self.send_commands(
  File "/home/ilya/.local/lib/python3.10/site-packages/scrapli/driver/network/sync_driver.py", line 294, in send_commands
    responses = super().send_commands(
  File "/home/ilya/.local/lib/python3.10/site-packages/scrapli/driver/generic/sync_driver.py", line 215, in send_commands
    response = self._send_command(
  File "/home/ilya/.local/lib/python3.10/site-packages/scrapli/decorators.py", line 297, in decorate
    result = wrapped_func(*args, **kwargs)
  File "/home/ilya/.local/lib/python3.10/site-packages/scrapli/driver/generic/sync_driver.py", line 138, in _send_command
    raw_response, processed_response = self.channel.send_input(
  File "/home/ilya/.local/lib/python3.10/site-packages/scrapli/decorators.py", line 216, in decorate
    return _multiprocessing_timeout(
  File "/home/ilya/.local/lib/python3.10/site-packages/scrapli/decorators.py", line 108, in _multiprocessing_timeout
    return _handle_timeout(
  File "/home/ilya/.local/lib/python3.10/site-packages/scrapli/decorators.py", line 134, in _handle_timeout
    raise ScrapliTimeout(message)
scrapli.exceptions.ScrapliTimeout: timed out sending input to device

2023-02-10 11:31:00,146 - nornir.core.task -    ERROR -      start() - Host 'R2': task 'send_file' failed with traceback:
Traceback (most recent call last):
  File "/home/ilya/.local/lib/python3.10/site-packages/nornir/core/task.py", line 99, in start
    r = self.task(self, **self.params)
  File "/home/ilya/Nornir_Labs/send_from_file.py", line 8, in send_file
    task.run(task=send_commands_from_file, file="commands.txt")
  File "/home/ilya/.local/lib/python3.10/site-packages/nornir/core/task.py", line 174, in run
    raise NornirSubTaskError(task=run_task, result=r)
nornir.core.exceptions.NornirSubTaskError: Subtask: send_commands_from_file (failed)


2023-02-10 11:31:00,151 - nornir.core.task -    ERROR -      start() - Host 'R5': task 'send_commands_from_file' failed with traceback:
Traceback (most recent call last):
  File "/home/ilya/.local/lib/python3.10/site-packages/nornir/core/task.py", line 99, in start
    r = self.task(self, **self.params)
  File "/home/ilya/.local/lib/python3.10/site-packages/nornir_scrapli/tasks/core/send_commands_from_file.py", line 43, in send_commands_from_file
    scrapli_response = scrapli_conn.send_commands_from_file(
  File "/home/ilya/.local/lib/python3.10/site-packages/scrapli/driver/network/sync_driver.py", line 347, in send_commands_from_file
    return super().send_commands_from_file(
  File "/home/ilya/.local/lib/python3.10/site-packages/scrapli/driver/generic/sync_driver.py", line 277, in send_commands_from_file
    return self.send_commands(
  File "/home/ilya/.local/lib/python3.10/site-packages/scrapli/driver/network/sync_driver.py", line 294, in send_commands
    responses = super().send_commands(
  File "/home/ilya/.local/lib/python3.10/site-packages/scrapli/driver/generic/sync_driver.py", line 215, in send_commands
    response = self._send_command(
  File "/home/ilya/.local/lib/python3.10/site-packages/scrapli/decorators.py", line 297, in decorate
    result = wrapped_func(*args, **kwargs)
  File "/home/ilya/.local/lib/python3.10/site-packages/scrapli/driver/generic/sync_driver.py", line 138, in _send_command
    raw_response, processed_response = self.channel.send_input(
  File "/home/ilya/.local/lib/python3.10/site-packages/scrapli/decorators.py", line 216, in decorate
    return _multiprocessing_timeout(
  File "/home/ilya/.local/lib/python3.10/site-packages/scrapli/decorators.py", line 108, in _multiprocessing_timeout
    return _handle_timeout(
  File "/home/ilya/.local/lib/python3.10/site-packages/scrapli/decorators.py", line 134, in _handle_timeout
    raise ScrapliTimeout(message)
scrapli.exceptions.ScrapliTimeout: timed out sending input to device

2023-02-10 11:31:00,151 - nornir.core.task -    ERROR -      start() - Host 'R5': task 'send_file' failed with traceback:
Traceback (most recent call last):
  File "/home/ilya/.local/lib/python3.10/site-packages/nornir/core/task.py", line 99, in start
    r = self.task(self, **self.params)
  File "/home/ilya/Nornir_Labs/send_from_file.py", line 8, in send_file
    task.run(task=send_commands_from_file, file="commands.txt")
  File "/home/ilya/.local/lib/python3.10/site-packages/nornir/core/task.py", line 174, in run
    raise NornirSubTaskError(task=run_task, result=r)
nornir.core.exceptions.NornirSubTaskError: Subtask: send_commands_from_file (failed)


2023-02-10 11:31:00,167 - nornir.core.task -    ERROR -      start() - Host 'R1': task 'send_commands_from_file' failed with traceback:
Traceback (most recent call last):
  File "/home/ilya/.local/lib/python3.10/site-packages/nornir/core/task.py", line 99, in start
    r = self.task(self, **self.params)
  File "/home/ilya/.local/lib/python3.10/site-packages/nornir_scrapli/tasks/core/send_commands_from_file.py", line 43, in send_commands_from_file
    scrapli_response = scrapli_conn.send_commands_from_file(
  File "/home/ilya/.local/lib/python3.10/site-packages/scrapli/driver/network/sync_driver.py", line 347, in send_commands_from_file
    return super().send_commands_from_file(
  File "/home/ilya/.local/lib/python3.10/site-packages/scrapli/driver/generic/sync_driver.py", line 277, in send_commands_from_file
    return self.send_commands(
  File "/home/ilya/.local/lib/python3.10/site-packages/scrapli/driver/network/sync_driver.py", line 294, in send_commands
    responses = super().send_commands(
  File "/home/ilya/.local/lib/python3.10/site-packages/scrapli/driver/generic/sync_driver.py", line 215, in send_commands
    response = self._send_command(
  File "/home/ilya/.local/lib/python3.10/site-packages/scrapli/decorators.py", line 297, in decorate
    result = wrapped_func(*args, **kwargs)
  File "/home/ilya/.local/lib/python3.10/site-packages/scrapli/driver/generic/sync_driver.py", line 138, in _send_command
    raw_response, processed_response = self.channel.send_input(
  File "/home/ilya/.local/lib/python3.10/site-packages/scrapli/decorators.py", line 216, in decorate
    return _multiprocessing_timeout(
  File "/home/ilya/.local/lib/python3.10/site-packages/scrapli/decorators.py", line 108, in _multiprocessing_timeout
    return _handle_timeout(
  File "/home/ilya/.local/lib/python3.10/site-packages/scrapli/decorators.py", line 134, in _handle_timeout
    raise ScrapliTimeout(message)
scrapli.exceptions.ScrapliTimeout: timed out sending input to device

2023-02-10 11:31:00,167 - nornir.core.task -    ERROR -      start() - Host 'R1': task 'send_file' failed with traceback:
Traceback (most recent call last):
  File "/home/ilya/.local/lib/python3.10/site-packages/nornir/core/task.py", line 99, in start
    r = self.task(self, **self.params)
  File "/home/ilya/Nornir_Labs/send_from_file.py", line 8, in send_file
    task.run(task=send_commands_from_file, file="commands.txt")
  File "/home/ilya/.local/lib/python3.10/site-packages/nornir/core/task.py", line 174, in run
    raise NornirSubTaskError(task=run_task, result=r)
nornir.core.exceptions.NornirSubTaskError: Subtask: send_commands_from_file (failed)


2023-02-10 11:31:00,190 - nornir.core.task -    ERROR -      start() - Host 'R3': task 'send_commands_from_file' failed with traceback:
Traceback (most recent call last):
  File "/home/ilya/.local/lib/python3.10/site-packages/nornir/core/task.py", line 99, in start
    r = self.task(self, **self.params)
  File "/home/ilya/.local/lib/python3.10/site-packages/nornir_scrapli/tasks/core/send_commands_from_file.py", line 43, in send_commands_from_file
    scrapli_response = scrapli_conn.send_commands_from_file(
  File "/home/ilya/.local/lib/python3.10/site-packages/scrapli/driver/network/sync_driver.py", line 347, in send_commands_from_file
    return super().send_commands_from_file(
  File "/home/ilya/.local/lib/python3.10/site-packages/scrapli/driver/generic/sync_driver.py", line 277, in send_commands_from_file
    return self.send_commands(
  File "/home/ilya/.local/lib/python3.10/site-packages/scrapli/driver/network/sync_driver.py", line 294, in send_commands
    responses = super().send_commands(
  File "/home/ilya/.local/lib/python3.10/site-packages/scrapli/driver/generic/sync_driver.py", line 215, in send_commands
    response = self._send_command(
  File "/home/ilya/.local/lib/python3.10/site-packages/scrapli/decorators.py", line 297, in decorate
    result = wrapped_func(*args, **kwargs)
  File "/home/ilya/.local/lib/python3.10/site-packages/scrapli/driver/generic/sync_driver.py", line 138, in _send_command
    raw_response, processed_response = self.channel.send_input(
  File "/home/ilya/.local/lib/python3.10/site-packages/scrapli/decorators.py", line 216, in decorate
    return _multiprocessing_timeout(
  File "/home/ilya/.local/lib/python3.10/site-packages/scrapli/decorators.py", line 108, in _multiprocessing_timeout
    return _handle_timeout(
  File "/home/ilya/.local/lib/python3.10/site-packages/scrapli/decorators.py", line 134, in _handle_timeout
    raise ScrapliTimeout(message)
scrapli.exceptions.ScrapliTimeout: timed out sending input to device

2023-02-10 11:31:00,190 - nornir.core.task -    ERROR -      start() - Host 'R3': task 'send_file' failed with traceback:
Traceback (most recent call last):
  File "/home/ilya/.local/lib/python3.10/site-packages/nornir/core/task.py", line 99, in start
    r = self.task(self, **self.params)
  File "/home/ilya/Nornir_Labs/send_from_file.py", line 8, in send_file
    task.run(task=send_commands_from_file, file="commands.txt")
  File "/home/ilya/.local/lib/python3.10/site-packages/nornir/core/task.py", line 174, in run
    raise NornirSubTaskError(task=run_task, result=r)
nornir.core.exceptions.NornirSubTaskError: Subtask: send_commands_from_file (failed)


2023-02-10 11:32:21,262 -  nornir.core -     INFO -        run() - Running task 'send_file' with args {} on 7 hosts
2023-02-10 11:32:39,560 -  nornir.core -     INFO -        run() - Running task 'send_file' with args {} on 7 hosts
2023-02-10 11:33:38,485 -  nornir.core -     INFO -        run() - Running task 'test_config' with args {} on 7 hosts
2023-02-10 11:33:39,227 -  nornir.core -     INFO -        run() - Running task 'write_mem' with args {} on 7 hosts
2023-02-10 11:35:50,949 -  nornir.core -     INFO -        run() - Running task 'test_config' with args {} on 7 hosts
2023-02-10 11:36:21,601 - nornir.core.task -    ERROR -      start() - Host 'R4': task 'send_configs' failed with traceback:
Traceback (most recent call last):
  File "/home/ilya/.local/lib/python3.10/site-packages/nornir/core/task.py", line 99, in start
    r = self.task(self, **self.params)
  File "/home/ilya/.local/lib/python3.10/site-packages/nornir_scrapli/tasks/core/send_configs.py", line 68, in send_configs
    scrapli_response = scrapli_conn.send_configs(
  File "/home/ilya/.local/lib/python3.10/site-packages/scrapli/driver/network/sync_driver.py", line 516, in send_configs
    responses = super().send_commands(
  File "/home/ilya/.local/lib/python3.10/site-packages/scrapli/driver/generic/sync_driver.py", line 215, in send_commands
    response = self._send_command(
  File "/home/ilya/.local/lib/python3.10/site-packages/scrapli/decorators.py", line 297, in decorate
    result = wrapped_func(*args, **kwargs)
  File "/home/ilya/.local/lib/python3.10/site-packages/scrapli/driver/generic/sync_driver.py", line 138, in _send_command
    raw_response, processed_response = self.channel.send_input(
  File "/home/ilya/.local/lib/python3.10/site-packages/scrapli/decorators.py", line 216, in decorate
    return _multiprocessing_timeout(
  File "/home/ilya/.local/lib/python3.10/site-packages/scrapli/decorators.py", line 108, in _multiprocessing_timeout
    return _handle_timeout(
  File "/home/ilya/.local/lib/python3.10/site-packages/scrapli/decorators.py", line 134, in _handle_timeout
    raise ScrapliTimeout(message)
scrapli.exceptions.ScrapliTimeout: timed out sending input to device

2023-02-10 11:36:21,601 - nornir.core.task -    ERROR -      start() - Host 'R4': task 'test_config' failed with traceback:
Traceback (most recent call last):
  File "/home/ilya/.local/lib/python3.10/site-packages/nornir/core/task.py", line 99, in start
    r = self.task(self, **self.params)
  File "/home/ilya/Nornir_Labs/runbook4.py", line 9, in test_config
    task.run(task=send_configs, configs=["no ip domain lookup", "no username ilya", "username ilya priv 15 secret cisco123"])
  File "/home/ilya/.local/lib/python3.10/site-packages/nornir/core/task.py", line 174, in run
    raise NornirSubTaskError(task=run_task, result=r)
nornir.core.exceptions.NornirSubTaskError: Subtask: send_configs (failed)


2023-02-10 11:36:21,606 - nornir.core.task -    ERROR -      start() - Host 'R6': task 'send_configs' failed with traceback:
Traceback (most recent call last):
  File "/home/ilya/.local/lib/python3.10/site-packages/nornir/core/task.py", line 99, in start
    r = self.task(self, **self.params)
  File "/home/ilya/.local/lib/python3.10/site-packages/nornir_scrapli/tasks/core/send_configs.py", line 68, in send_configs
    scrapli_response = scrapli_conn.send_configs(
  File "/home/ilya/.local/lib/python3.10/site-packages/scrapli/driver/network/sync_driver.py", line 516, in send_configs
    responses = super().send_commands(
  File "/home/ilya/.local/lib/python3.10/site-packages/scrapli/driver/generic/sync_driver.py", line 215, in send_commands
    response = self._send_command(
  File "/home/ilya/.local/lib/python3.10/site-packages/scrapli/decorators.py", line 297, in decorate
    result = wrapped_func(*args, **kwargs)
  File "/home/ilya/.local/lib/python3.10/site-packages/scrapli/driver/generic/sync_driver.py", line 138, in _send_command
    raw_response, processed_response = self.channel.send_input(
  File "/home/ilya/.local/lib/python3.10/site-packages/scrapli/decorators.py", line 216, in decorate
    return _multiprocessing_timeout(
  File "/home/ilya/.local/lib/python3.10/site-packages/scrapli/decorators.py", line 108, in _multiprocessing_timeout
    return _handle_timeout(
  File "/home/ilya/.local/lib/python3.10/site-packages/scrapli/decorators.py", line 134, in _handle_timeout
    raise ScrapliTimeout(message)
scrapli.exceptions.ScrapliTimeout: timed out sending input to device

2023-02-10 11:36:21,606 - nornir.core.task -    ERROR -      start() - Host 'R6': task 'test_config' failed with traceback:
Traceback (most recent call last):
  File "/home/ilya/.local/lib/python3.10/site-packages/nornir/core/task.py", line 99, in start
    r = self.task(self, **self.params)
  File "/home/ilya/Nornir_Labs/runbook4.py", line 9, in test_config
    task.run(task=send_configs, configs=["no ip domain lookup", "no username ilya", "username ilya priv 15 secret cisco123"])
  File "/home/ilya/.local/lib/python3.10/site-packages/nornir/core/task.py", line 174, in run
    raise NornirSubTaskError(task=run_task, result=r)
nornir.core.exceptions.NornirSubTaskError: Subtask: send_configs (failed)


2023-02-10 11:36:21,626 - nornir.core.task -    ERROR -      start() - Host 'R5': task 'send_configs' failed with traceback:
Traceback (most recent call last):
  File "/home/ilya/.local/lib/python3.10/site-packages/nornir/core/task.py", line 99, in start
    r = self.task(self, **self.params)
  File "/home/ilya/.local/lib/python3.10/site-packages/nornir_scrapli/tasks/core/send_configs.py", line 68, in send_configs
    scrapli_response = scrapli_conn.send_configs(
  File "/home/ilya/.local/lib/python3.10/site-packages/scrapli/driver/network/sync_driver.py", line 516, in send_configs
    responses = super().send_commands(
  File "/home/ilya/.local/lib/python3.10/site-packages/scrapli/driver/generic/sync_driver.py", line 215, in send_commands
    response = self._send_command(
  File "/home/ilya/.local/lib/python3.10/site-packages/scrapli/decorators.py", line 297, in decorate
    result = wrapped_func(*args, **kwargs)
  File "/home/ilya/.local/lib/python3.10/site-packages/scrapli/driver/generic/sync_driver.py", line 138, in _send_command
    raw_response, processed_response = self.channel.send_input(
  File "/home/ilya/.local/lib/python3.10/site-packages/scrapli/decorators.py", line 216, in decorate
    return _multiprocessing_timeout(
  File "/home/ilya/.local/lib/python3.10/site-packages/scrapli/decorators.py", line 108, in _multiprocessing_timeout
    return _handle_timeout(
  File "/home/ilya/.local/lib/python3.10/site-packages/scrapli/decorators.py", line 134, in _handle_timeout
    raise ScrapliTimeout(message)
scrapli.exceptions.ScrapliTimeout: timed out sending input to device

2023-02-10 11:36:21,627 - nornir.core.task -    ERROR -      start() - Host 'R5': task 'test_config' failed with traceback:
Traceback (most recent call last):
  File "/home/ilya/.local/lib/python3.10/site-packages/nornir/core/task.py", line 99, in start
    r = self.task(self, **self.params)
  File "/home/ilya/Nornir_Labs/runbook4.py", line 9, in test_config
    task.run(task=send_configs, configs=["no ip domain lookup", "no username ilya", "username ilya priv 15 secret cisco123"])
  File "/home/ilya/.local/lib/python3.10/site-packages/nornir/core/task.py", line 174, in run
    raise NornirSubTaskError(task=run_task, result=r)
nornir.core.exceptions.NornirSubTaskError: Subtask: send_configs (failed)


2023-02-10 11:36:21,670 - nornir.core.task -    ERROR -      start() - Host 'R7': task 'send_configs' failed with traceback:
Traceback (most recent call last):
  File "/home/ilya/.local/lib/python3.10/site-packages/nornir/core/task.py", line 99, in start
    r = self.task(self, **self.params)
  File "/home/ilya/.local/lib/python3.10/site-packages/nornir_scrapli/tasks/core/send_configs.py", line 68, in send_configs
    scrapli_response = scrapli_conn.send_configs(
  File "/home/ilya/.local/lib/python3.10/site-packages/scrapli/driver/network/sync_driver.py", line 516, in send_configs
    responses = super().send_commands(
  File "/home/ilya/.local/lib/python3.10/site-packages/scrapli/driver/generic/sync_driver.py", line 215, in send_commands
    response = self._send_command(
  File "/home/ilya/.local/lib/python3.10/site-packages/scrapli/decorators.py", line 297, in decorate
    result = wrapped_func(*args, **kwargs)
  File "/home/ilya/.local/lib/python3.10/site-packages/scrapli/driver/generic/sync_driver.py", line 138, in _send_command
    raw_response, processed_response = self.channel.send_input(
  File "/home/ilya/.local/lib/python3.10/site-packages/scrapli/decorators.py", line 216, in decorate
    return _multiprocessing_timeout(
  File "/home/ilya/.local/lib/python3.10/site-packages/scrapli/decorators.py", line 108, in _multiprocessing_timeout
    return _handle_timeout(
  File "/home/ilya/.local/lib/python3.10/site-packages/scrapli/decorators.py", line 134, in _handle_timeout
    raise ScrapliTimeout(message)
scrapli.exceptions.ScrapliTimeout: timed out sending input to device

2023-02-10 11:36:21,670 - nornir.core.task -    ERROR -      start() - Host 'R7': task 'test_config' failed with traceback:
Traceback (most recent call last):
  File "/home/ilya/.local/lib/python3.10/site-packages/nornir/core/task.py", line 99, in start
    r = self.task(self, **self.params)
  File "/home/ilya/Nornir_Labs/runbook4.py", line 9, in test_config
    task.run(task=send_configs, configs=["no ip domain lookup", "no username ilya", "username ilya priv 15 secret cisco123"])
  File "/home/ilya/.local/lib/python3.10/site-packages/nornir/core/task.py", line 174, in run
    raise NornirSubTaskError(task=run_task, result=r)
nornir.core.exceptions.NornirSubTaskError: Subtask: send_configs (failed)


2023-02-10 11:36:21,684 - nornir.core.task -    ERROR -      start() - Host 'R2': task 'send_configs' failed with traceback:
Traceback (most recent call last):
  File "/home/ilya/.local/lib/python3.10/site-packages/nornir/core/task.py", line 99, in start
    r = self.task(self, **self.params)
  File "/home/ilya/.local/lib/python3.10/site-packages/nornir_scrapli/tasks/core/send_configs.py", line 68, in send_configs
    scrapli_response = scrapli_conn.send_configs(
  File "/home/ilya/.local/lib/python3.10/site-packages/scrapli/driver/network/sync_driver.py", line 516, in send_configs
    responses = super().send_commands(
  File "/home/ilya/.local/lib/python3.10/site-packages/scrapli/driver/generic/sync_driver.py", line 215, in send_commands
    response = self._send_command(
  File "/home/ilya/.local/lib/python3.10/site-packages/scrapli/decorators.py", line 297, in decorate
    result = wrapped_func(*args, **kwargs)
  File "/home/ilya/.local/lib/python3.10/site-packages/scrapli/driver/generic/sync_driver.py", line 138, in _send_command
    raw_response, processed_response = self.channel.send_input(
  File "/home/ilya/.local/lib/python3.10/site-packages/scrapli/decorators.py", line 216, in decorate
    return _multiprocessing_timeout(
  File "/home/ilya/.local/lib/python3.10/site-packages/scrapli/decorators.py", line 108, in _multiprocessing_timeout
    return _handle_timeout(
  File "/home/ilya/.local/lib/python3.10/site-packages/scrapli/decorators.py", line 134, in _handle_timeout
    raise ScrapliTimeout(message)
scrapli.exceptions.ScrapliTimeout: timed out sending input to device

2023-02-10 11:36:21,685 - nornir.core.task -    ERROR -      start() - Host 'R2': task 'test_config' failed with traceback:
Traceback (most recent call last):
  File "/home/ilya/.local/lib/python3.10/site-packages/nornir/core/task.py", line 99, in start
    r = self.task(self, **self.params)
  File "/home/ilya/Nornir_Labs/runbook4.py", line 9, in test_config
    task.run(task=send_configs, configs=["no ip domain lookup", "no username ilya", "username ilya priv 15 secret cisco123"])
  File "/home/ilya/.local/lib/python3.10/site-packages/nornir/core/task.py", line 174, in run
    raise NornirSubTaskError(task=run_task, result=r)
nornir.core.exceptions.NornirSubTaskError: Subtask: send_configs (failed)


2023-02-10 11:36:21,720 - nornir.core.task -    ERROR -      start() - Host 'R1': task 'send_configs' failed with traceback:
Traceback (most recent call last):
  File "/home/ilya/.local/lib/python3.10/site-packages/nornir/core/task.py", line 99, in start
    r = self.task(self, **self.params)
  File "/home/ilya/.local/lib/python3.10/site-packages/nornir_scrapli/tasks/core/send_configs.py", line 68, in send_configs
    scrapli_response = scrapli_conn.send_configs(
  File "/home/ilya/.local/lib/python3.10/site-packages/scrapli/driver/network/sync_driver.py", line 516, in send_configs
    responses = super().send_commands(
  File "/home/ilya/.local/lib/python3.10/site-packages/scrapli/driver/generic/sync_driver.py", line 215, in send_commands
    response = self._send_command(
  File "/home/ilya/.local/lib/python3.10/site-packages/scrapli/decorators.py", line 297, in decorate
    result = wrapped_func(*args, **kwargs)
  File "/home/ilya/.local/lib/python3.10/site-packages/scrapli/driver/generic/sync_driver.py", line 138, in _send_command
    raw_response, processed_response = self.channel.send_input(
  File "/home/ilya/.local/lib/python3.10/site-packages/scrapli/decorators.py", line 216, in decorate
    return _multiprocessing_timeout(
  File "/home/ilya/.local/lib/python3.10/site-packages/scrapli/decorators.py", line 108, in _multiprocessing_timeout
    return _handle_timeout(
  File "/home/ilya/.local/lib/python3.10/site-packages/scrapli/decorators.py", line 134, in _handle_timeout
    raise ScrapliTimeout(message)
scrapli.exceptions.ScrapliTimeout: timed out sending input to device

2023-02-10 11:36:21,720 - nornir.core.task -    ERROR -      start() - Host 'R1': task 'test_config' failed with traceback:
Traceback (most recent call last):
  File "/home/ilya/.local/lib/python3.10/site-packages/nornir/core/task.py", line 99, in start
    r = self.task(self, **self.params)
  File "/home/ilya/Nornir_Labs/runbook4.py", line 9, in test_config
    task.run(task=send_configs, configs=["no ip domain lookup", "no username ilya", "username ilya priv 15 secret cisco123"])
  File "/home/ilya/.local/lib/python3.10/site-packages/nornir/core/task.py", line 174, in run
    raise NornirSubTaskError(task=run_task, result=r)
nornir.core.exceptions.NornirSubTaskError: Subtask: send_configs (failed)


2023-02-10 11:36:21,776 - nornir.core.task -    ERROR -      start() - Host 'R3': task 'send_configs' failed with traceback:
Traceback (most recent call last):
  File "/home/ilya/.local/lib/python3.10/site-packages/nornir/core/task.py", line 99, in start
    r = self.task(self, **self.params)
  File "/home/ilya/.local/lib/python3.10/site-packages/nornir_scrapli/tasks/core/send_configs.py", line 68, in send_configs
    scrapli_response = scrapli_conn.send_configs(
  File "/home/ilya/.local/lib/python3.10/site-packages/scrapli/driver/network/sync_driver.py", line 516, in send_configs
    responses = super().send_commands(
  File "/home/ilya/.local/lib/python3.10/site-packages/scrapli/driver/generic/sync_driver.py", line 215, in send_commands
    response = self._send_command(
  File "/home/ilya/.local/lib/python3.10/site-packages/scrapli/decorators.py", line 297, in decorate
    result = wrapped_func(*args, **kwargs)
  File "/home/ilya/.local/lib/python3.10/site-packages/scrapli/driver/generic/sync_driver.py", line 138, in _send_command
    raw_response, processed_response = self.channel.send_input(
  File "/home/ilya/.local/lib/python3.10/site-packages/scrapli/decorators.py", line 216, in decorate
    return _multiprocessing_timeout(
  File "/home/ilya/.local/lib/python3.10/site-packages/scrapli/decorators.py", line 108, in _multiprocessing_timeout
    return _handle_timeout(
  File "/home/ilya/.local/lib/python3.10/site-packages/scrapli/decorators.py", line 134, in _handle_timeout
    raise ScrapliTimeout(message)
scrapli.exceptions.ScrapliTimeout: timed out sending input to device

2023-02-10 11:36:21,776 - nornir.core.task -    ERROR -      start() - Host 'R3': task 'test_config' failed with traceback:
Traceback (most recent call last):
  File "/home/ilya/.local/lib/python3.10/site-packages/nornir/core/task.py", line 99, in start
    r = self.task(self, **self.params)
  File "/home/ilya/Nornir_Labs/runbook4.py", line 9, in test_config
    task.run(task=send_configs, configs=["no ip domain lookup", "no username ilya", "username ilya priv 15 secret cisco123"])
  File "/home/ilya/.local/lib/python3.10/site-packages/nornir/core/task.py", line 174, in run
    raise NornirSubTaskError(task=run_task, result=r)
nornir.core.exceptions.NornirSubTaskError: Subtask: send_configs (failed)


2023-02-10 11:36:21,776 -  nornir.core -     INFO -        run() - Running task 'write_mem' with args {} on 7 hosts
2023-02-10 11:37:32,288 -  nornir.core -     INFO -        run() - Running task 'test_config' with args {} on 7 hosts
2023-02-10 11:37:32,832 -  nornir.core -     INFO -        run() - Running task 'write_mem' with args {} on 7 hosts
2023-02-10 11:39:11,057 -  nornir.core -     INFO -        run() - Running task 'test_config' with args {} on 7 hosts
2023-02-10 11:39:11,615 -  nornir.core -     INFO -        run() - Running task 'write_mem' with args {} on 7 hosts
2023-02-10 11:54:35,651 -  nornir.core -     INFO -        run() - Running task 'show_command_test' with args {} on 7 hosts
2023-02-10 13:21:59,940 -  nornir.core -     INFO -        run() - Running task 'show_command_test' with args {} on 7 hosts
2023-02-10 13:22:14,986 - nornir.core.task -    ERROR -      start() - Host 'R7': task 'send_commands' failed with traceback:
Traceback (most recent call last):
  File "/home/ilya/.local/lib/python3.10/site-packages/nornir/core/task.py", line 99, in start
    r = self.task(self, **self.params)
  File "/home/ilya/.local/lib/python3.10/site-packages/nornir_scrapli/tasks/core/send_commands.py", line 43, in send_commands
    scrapli_conn = task.host.get_connection("scrapli", task.nornir.config)
  File "/home/ilya/.local/lib/python3.10/site-packages/nornir/core/inventory.py", line 494, in get_connection
    self.open_connection(
  File "/home/ilya/.local/lib/python3.10/site-packages/nornir/core/inventory.py", line 546, in open_connection
    conn_obj.open(
  File "/home/ilya/.local/lib/python3.10/site-packages/nornir_scrapli/connection.py", line 105, in open
    connection.open()
  File "/home/ilya/.local/lib/python3.10/site-packages/scrapli/driver/base/sync_driver.py", line 88, in open
    self.channel.channel_authenticate_ssh(
  File "/home/ilya/.local/lib/python3.10/site-packages/scrapli/decorators.py", line 216, in decorate
    return _multiprocessing_timeout(
  File "/home/ilya/.local/lib/python3.10/site-packages/scrapli/decorators.py", line 113, in _multiprocessing_timeout
    return future.result()
  File "/usr/lib/python3.10/concurrent/futures/_base.py", line 451, in result
    return self.__get_result()
  File "/usr/lib/python3.10/concurrent/futures/_base.py", line 403, in __get_result
    raise self._exception
  File "/usr/lib/python3.10/concurrent/futures/thread.py", line 58, in run
    result = self.fn(*self.args, **self.kwargs)
  File "/home/ilya/.local/lib/python3.10/site-packages/scrapli/channel/sync_channel.py", line 290, in channel_authenticate_ssh
    self._ssh_message_handler(output=authenticate_buf)
  File "/home/ilya/.local/lib/python3.10/site-packages/scrapli/channel/base_channel.py", line 432, in _ssh_message_handler
    raise ScrapliAuthenticationFailed(msg)
scrapli.exceptions.ScrapliAuthenticationFailed: Timed out connecting to host

2023-02-10 13:22:14,986 - nornir.core.task -    ERROR -      start() - Host 'R7': task 'show_command_test' failed with traceback:
Traceback (most recent call last):
  File "/home/ilya/.local/lib/python3.10/site-packages/nornir/core/task.py", line 99, in start
    r = self.task(self, **self.params)
  File "/home/ilya/Nornir_Labs/runbook3.py", line 7, in show_command_test
    task.run(task=send_commands, commands=["show users"])
  File "/home/ilya/.local/lib/python3.10/site-packages/nornir/core/task.py", line 174, in run
    raise NornirSubTaskError(task=run_task, result=r)
nornir.core.exceptions.NornirSubTaskError: Subtask: send_commands (failed)


2023-02-10 13:22:14,992 - nornir.core.task -    ERROR -      start() - Host 'R4': task 'send_commands' failed with traceback:
Traceback (most recent call last):
  File "/home/ilya/.local/lib/python3.10/site-packages/nornir/core/task.py", line 99, in start
    r = self.task(self, **self.params)
  File "/home/ilya/.local/lib/python3.10/site-packages/nornir_scrapli/tasks/core/send_commands.py", line 43, in send_commands
    scrapli_conn = task.host.get_connection("scrapli", task.nornir.config)
  File "/home/ilya/.local/lib/python3.10/site-packages/nornir/core/inventory.py", line 494, in get_connection
    self.open_connection(
  File "/home/ilya/.local/lib/python3.10/site-packages/nornir/core/inventory.py", line 546, in open_connection
    conn_obj.open(
  File "/home/ilya/.local/lib/python3.10/site-packages/nornir_scrapli/connection.py", line 105, in open
    connection.open()
  File "/home/ilya/.local/lib/python3.10/site-packages/scrapli/driver/base/sync_driver.py", line 88, in open
    self.channel.channel_authenticate_ssh(
  File "/home/ilya/.local/lib/python3.10/site-packages/scrapli/decorators.py", line 216, in decorate
    return _multiprocessing_timeout(
  File "/home/ilya/.local/lib/python3.10/site-packages/scrapli/decorators.py", line 113, in _multiprocessing_timeout
    return future.result()
  File "/usr/lib/python3.10/concurrent/futures/_base.py", line 451, in result
    return self.__get_result()
  File "/usr/lib/python3.10/concurrent/futures/_base.py", line 403, in __get_result
    raise self._exception
  File "/usr/lib/python3.10/concurrent/futures/thread.py", line 58, in run
    result = self.fn(*self.args, **self.kwargs)
  File "/home/ilya/.local/lib/python3.10/site-packages/scrapli/channel/sync_channel.py", line 290, in channel_authenticate_ssh
    self._ssh_message_handler(output=authenticate_buf)
  File "/home/ilya/.local/lib/python3.10/site-packages/scrapli/channel/base_channel.py", line 432, in _ssh_message_handler
    raise ScrapliAuthenticationFailed(msg)
scrapli.exceptions.ScrapliAuthenticationFailed: Timed out connecting to host

2023-02-10 13:22:14,992 - nornir.core.task -    ERROR -      start() - Host 'R4': task 'show_command_test' failed with traceback:
Traceback (most recent call last):
  File "/home/ilya/.local/lib/python3.10/site-packages/nornir/core/task.py", line 99, in start
    r = self.task(self, **self.params)
  File "/home/ilya/Nornir_Labs/runbook3.py", line 7, in show_command_test
    task.run(task=send_commands, commands=["show users"])
  File "/home/ilya/.local/lib/python3.10/site-packages/nornir/core/task.py", line 174, in run
    raise NornirSubTaskError(task=run_task, result=r)
nornir.core.exceptions.NornirSubTaskError: Subtask: send_commands (failed)


2023-02-10 13:22:14,995 - nornir.core.task -    ERROR -      start() - Host 'R6': task 'send_commands' failed with traceback:
Traceback (most recent call last):
  File "/home/ilya/.local/lib/python3.10/site-packages/nornir/core/task.py", line 99, in start
    r = self.task(self, **self.params)
  File "/home/ilya/.local/lib/python3.10/site-packages/nornir_scrapli/tasks/core/send_commands.py", line 43, in send_commands
    scrapli_conn = task.host.get_connection("scrapli", task.nornir.config)
  File "/home/ilya/.local/lib/python3.10/site-packages/nornir/core/inventory.py", line 494, in get_connection
    self.open_connection(
  File "/home/ilya/.local/lib/python3.10/site-packages/nornir/core/inventory.py", line 546, in open_connection
    conn_obj.open(
  File "/home/ilya/.local/lib/python3.10/site-packages/nornir_scrapli/connection.py", line 105, in open
    connection.open()
  File "/home/ilya/.local/lib/python3.10/site-packages/scrapli/driver/base/sync_driver.py", line 88, in open
    self.channel.channel_authenticate_ssh(
  File "/home/ilya/.local/lib/python3.10/site-packages/scrapli/decorators.py", line 216, in decorate
    return _multiprocessing_timeout(
  File "/home/ilya/.local/lib/python3.10/site-packages/scrapli/decorators.py", line 113, in _multiprocessing_timeout
    return future.result()
  File "/usr/lib/python3.10/concurrent/futures/_base.py", line 451, in result
    return self.__get_result()
  File "/usr/lib/python3.10/concurrent/futures/_base.py", line 403, in __get_result
    raise self._exception
  File "/usr/lib/python3.10/concurrent/futures/thread.py", line 58, in run
    result = self.fn(*self.args, **self.kwargs)
  File "/home/ilya/.local/lib/python3.10/site-packages/scrapli/channel/sync_channel.py", line 290, in channel_authenticate_ssh
    self._ssh_message_handler(output=authenticate_buf)
  File "/home/ilya/.local/lib/python3.10/site-packages/scrapli/channel/base_channel.py", line 432, in _ssh_message_handler
    raise ScrapliAuthenticationFailed(msg)
scrapli.exceptions.ScrapliAuthenticationFailed: Timed out connecting to host

2023-02-10 13:22:14,995 - nornir.core.task -    ERROR -      start() - Host 'R6': task 'show_command_test' failed with traceback:
Traceback (most recent call last):
  File "/home/ilya/.local/lib/python3.10/site-packages/nornir/core/task.py", line 99, in start
    r = self.task(self, **self.params)
  File "/home/ilya/Nornir_Labs/runbook3.py", line 7, in show_command_test
    task.run(task=send_commands, commands=["show users"])
  File "/home/ilya/.local/lib/python3.10/site-packages/nornir/core/task.py", line 174, in run
    raise NornirSubTaskError(task=run_task, result=r)
nornir.core.exceptions.NornirSubTaskError: Subtask: send_commands (failed)


2023-02-10 13:22:15,002 - nornir.core.task -    ERROR -      start() - Host 'R5': task 'send_commands' failed with traceback:
Traceback (most recent call last):
  File "/home/ilya/.local/lib/python3.10/site-packages/nornir/core/task.py", line 99, in start
    r = self.task(self, **self.params)
  File "/home/ilya/.local/lib/python3.10/site-packages/nornir_scrapli/tasks/core/send_commands.py", line 43, in send_commands
    scrapli_conn = task.host.get_connection("scrapli", task.nornir.config)
  File "/home/ilya/.local/lib/python3.10/site-packages/nornir/core/inventory.py", line 494, in get_connection
    self.open_connection(
  File "/home/ilya/.local/lib/python3.10/site-packages/nornir/core/inventory.py", line 546, in open_connection
    conn_obj.open(
  File "/home/ilya/.local/lib/python3.10/site-packages/nornir_scrapli/connection.py", line 105, in open
    connection.open()
  File "/home/ilya/.local/lib/python3.10/site-packages/scrapli/driver/base/sync_driver.py", line 88, in open
    self.channel.channel_authenticate_ssh(
  File "/home/ilya/.local/lib/python3.10/site-packages/scrapli/decorators.py", line 216, in decorate
    return _multiprocessing_timeout(
  File "/home/ilya/.local/lib/python3.10/site-packages/scrapli/decorators.py", line 113, in _multiprocessing_timeout
    return future.result()
  File "/usr/lib/python3.10/concurrent/futures/_base.py", line 451, in result
    return self.__get_result()
  File "/usr/lib/python3.10/concurrent/futures/_base.py", line 403, in __get_result
    raise self._exception
  File "/usr/lib/python3.10/concurrent/futures/thread.py", line 58, in run
    result = self.fn(*self.args, **self.kwargs)
  File "/home/ilya/.local/lib/python3.10/site-packages/scrapli/channel/sync_channel.py", line 290, in channel_authenticate_ssh
    self._ssh_message_handler(output=authenticate_buf)
  File "/home/ilya/.local/lib/python3.10/site-packages/scrapli/channel/base_channel.py", line 432, in _ssh_message_handler
    raise ScrapliAuthenticationFailed(msg)
scrapli.exceptions.ScrapliAuthenticationFailed: Timed out connecting to host

2023-02-10 13:22:15,002 - nornir.core.task -    ERROR -      start() - Host 'R5': task 'show_command_test' failed with traceback:
Traceback (most recent call last):
  File "/home/ilya/.local/lib/python3.10/site-packages/nornir/core/task.py", line 99, in start
    r = self.task(self, **self.params)
  File "/home/ilya/Nornir_Labs/runbook3.py", line 7, in show_command_test
    task.run(task=send_commands, commands=["show users"])
  File "/home/ilya/.local/lib/python3.10/site-packages/nornir/core/task.py", line 174, in run
    raise NornirSubTaskError(task=run_task, result=r)
nornir.core.exceptions.NornirSubTaskError: Subtask: send_commands (failed)


2023-02-10 13:32:12,020 -  nornir.core -     INFO -        run() - Running task 'show_command_test' with args {} on 7 hosts
2023-02-10 13:41:45,939 -  nornir.core -     INFO -        run() - Running task 'show_command_test' with args {} on 7 hosts
2023-02-10 13:42:20,253 -  nornir.core -     INFO -        run() - Running task 'backup_run_flash' with args {} on 7 hosts
2023-02-10 13:44:31,703 -  nornir.core -     INFO -        run() - Running task 'backup_run_flash' with args {} on 7 hosts
2023-02-10 13:46:08,926 -  nornir.core -     INFO -        run() - Running task 'backup_run_flash' with args {} on 7 hosts
2023-02-10 13:47:19,080 -  nornir.core -     INFO -        run() - Running task 'show_command_test' with args {} on 7 hosts
2023-02-10 13:54:20,072 -  nornir.core -     INFO -        run() - Running task 'backup_run_flash' with args {} on 7 hosts
2023-02-10 13:55:21,610 -  nornir.core -     INFO -        run() - Running task 'backup_run_flash' with args {} on 7 hosts
2023-02-10 14:02:28,148 -  nornir.core -     INFO -        run() - Running task 'backup_run_flash' with args {} on 7 hosts
2023-02-10 14:03:19,211 -  nornir.core -     INFO -        run() - Running task 'Restore_flash_run' with args {} on 7 hosts
2023-02-10 14:04:28,149 -  nornir.core -     INFO -        run() - Running task 'Restore_flash_run' with args {} on 7 hosts
2023-02-10 14:05:48,021 -  nornir.core -     INFO -        run() - Running task 'Restore_flash_run' with args {} on 7 hosts
2023-02-11 10:58:08,186 -  nornir.core -     INFO -        run() - Running task 'set_ip' with args {} on 1 hosts
2023-02-11 10:59:40,359 -  nornir.core -     INFO -        run() - Running task 'set_ip' with args {} on 2 hosts
2023-02-11 11:06:07,762 -  nornir.core -     INFO -        run() - Running task 'set_ip' with args {} on 2 hosts
2023-02-11 11:18:13,570 -  nornir.core -     INFO -        run() - Running task 'set_ip' with args {} on 1 hosts
2023-02-11 11:18:13,570 - nornir.core.task -    ERROR -      start() - Host 'R1': task 'set_ip' failed with traceback:
Traceback (most recent call last):
  File "/home/ilya/.local/lib/python3.10/site-packages/nornir/core/task.py", line 99, in start
    r = self.task(self, **self.params)
  File "/home/ilya/Nornir_Labs/print_inv.py", line 8, in set_ip
    array = {task.host['active_int_list']}
TypeError: unhashable type: 'list'

2023-02-11 11:21:40,124 -  nornir.core -     INFO -        run() - Running task 'set_ip' with args {} on 1 hosts
2023-02-11 11:21:40,125 - nornir.core.task -    ERROR -      start() - Host 'R1': task 'set_ip' failed with traceback:
Traceback (most recent call last):
  File "/home/ilya/.local/lib/python3.10/site-packages/nornir/core/task.py", line 99, in start
    r = self.task(self, **self.params)
  File "/home/ilya/Nornir_Labs/print_inv.py", line 8, in set_ip
    for host_int in {task.host['active_int_list']}:
TypeError: unhashable type: 'list'

2023-02-11 11:28:27,548 -  nornir.core -     INFO -        run() - Running task 'set_ip' with args {} on 2 hosts
2023-02-11 11:33:20,326 -  nornir.core -     INFO -        run() - Running task 'set_ip' with args {} on 2 hosts
2023-02-11 11:41:03,738 -  nornir.core -     INFO -        run() - Running task 'simple_send' with args {} on 7 hosts
2023-02-11 11:43:13,376 -  nornir.core -     INFO -        run() - Running task 'simple_send' with args {} on 7 hosts
2023-02-11 11:43:13,959 -  nornir.core -     INFO -        run() - Running task 'write_mem' with args {} on 7 hosts
2023-02-13 09:23:22,982 -  nornir.core -     INFO -        run() - Running task 'show_command_test' with args {} on 7 hosts
2023-02-13 09:24:22,924 -  nornir.core -     INFO -        run() - Running task 'show_command_test' with args {} on 7 hosts
2023-02-13 09:25:00,698 -  nornir.core -     INFO -        run() - Running task 'show_command_test' with args {} on 7 hosts
2023-02-13 09:36:45,196 -  nornir.core -     INFO -        run() - Running task 'conf_command_list' with args {} on 7 hosts
2023-02-13 09:36:45,198 - nornir.core.task -    ERROR -      start() - Host 'R1': task 'send_configs' failed with traceback:
Traceback (most recent call last):
  File "/home/ilya/.local/lib/python3.10/site-packages/nornir/core/task.py", line 99, in start
    r = self.task(self, **self.params)
TypeError: send_configs() got an unexpected keyword argument 'command'

2023-02-13 09:36:45,198 - nornir.core.task -    ERROR -      start() - Host 'R3': task 'send_configs' failed with traceback:
Traceback (most recent call last):
  File "/home/ilya/.local/lib/python3.10/site-packages/nornir/core/task.py", line 99, in start
    r = self.task(self, **self.params)
TypeError: send_configs() got an unexpected keyword argument 'command'

2023-02-13 09:36:45,199 - nornir.core.task -    ERROR -      start() - Host 'R3': task 'conf_command_list' failed with traceback:
Traceback (most recent call last):
  File "/home/ilya/.local/lib/python3.10/site-packages/nornir/core/task.py", line 99, in start
    r = self.task(self, **self.params)
  File "/home/ilya/Nornir_Labs/01_Essentials/05_Send_list_conf.py", line 11, in conf_command_list
    task.run(task=send_configs, command=cmd)
  File "/home/ilya/.local/lib/python3.10/site-packages/nornir/core/task.py", line 174, in run
    raise NornirSubTaskError(task=run_task, result=r)
nornir.core.exceptions.NornirSubTaskError: Subtask: send_configs (failed)


2023-02-13 09:36:45,198 - nornir.core.task -    ERROR -      start() - Host 'R2': task 'send_configs' failed with traceback:
Traceback (most recent call last):
  File "/home/ilya/.local/lib/python3.10/site-packages/nornir/core/task.py", line 99, in start
    r = self.task(self, **self.params)
TypeError: send_configs() got an unexpected keyword argument 'command'

2023-02-13 09:36:45,199 - nornir.core.task -    ERROR -      start() - Host 'R1': task 'conf_command_list' failed with traceback:
Traceback (most recent call last):
  File "/home/ilya/.local/lib/python3.10/site-packages/nornir/core/task.py", line 99, in start
    r = self.task(self, **self.params)
  File "/home/ilya/Nornir_Labs/01_Essentials/05_Send_list_conf.py", line 11, in conf_command_list
    task.run(task=send_configs, command=cmd)
  File "/home/ilya/.local/lib/python3.10/site-packages/nornir/core/task.py", line 174, in run
    raise NornirSubTaskError(task=run_task, result=r)
nornir.core.exceptions.NornirSubTaskError: Subtask: send_configs (failed)


2023-02-13 09:36:45,198 - nornir.core.task -    ERROR -      start() - Host 'R6': task 'send_configs' failed with traceback:
Traceback (most recent call last):
  File "/home/ilya/.local/lib/python3.10/site-packages/nornir/core/task.py", line 99, in start
    r = self.task(self, **self.params)
TypeError: send_configs() got an unexpected keyword argument 'command'

2023-02-13 09:36:45,199 - nornir.core.task -    ERROR -      start() - Host 'R5': task 'send_configs' failed with traceback:
Traceback (most recent call last):
  File "/home/ilya/.local/lib/python3.10/site-packages/nornir/core/task.py", line 99, in start
    r = self.task(self, **self.params)
TypeError: send_configs() got an unexpected keyword argument 'command'

2023-02-13 09:36:45,200 - nornir.core.task -    ERROR -      start() - Host 'R5': task 'conf_command_list' failed with traceback:
Traceback (most recent call last):
  File "/home/ilya/.local/lib/python3.10/site-packages/nornir/core/task.py", line 99, in start
    r = self.task(self, **self.params)
  File "/home/ilya/Nornir_Labs/01_Essentials/05_Send_list_conf.py", line 11, in conf_command_list
    task.run(task=send_configs, command=cmd)
  File "/home/ilya/.local/lib/python3.10/site-packages/nornir/core/task.py", line 174, in run
    raise NornirSubTaskError(task=run_task, result=r)
nornir.core.exceptions.NornirSubTaskError: Subtask: send_configs (failed)


2023-02-13 09:36:45,200 - nornir.core.task -    ERROR -      start() - Host 'R4': task 'send_configs' failed with traceback:
Traceback (most recent call last):
  File "/home/ilya/.local/lib/python3.10/site-packages/nornir/core/task.py", line 99, in start
    r = self.task(self, **self.params)
TypeError: send_configs() got an unexpected keyword argument 'command'

2023-02-13 09:36:45,200 - nornir.core.task -    ERROR -      start() - Host 'R2': task 'conf_command_list' failed with traceback:
Traceback (most recent call last):
  File "/home/ilya/.local/lib/python3.10/site-packages/nornir/core/task.py", line 99, in start
    r = self.task(self, **self.params)
  File "/home/ilya/Nornir_Labs/01_Essentials/05_Send_list_conf.py", line 11, in conf_command_list
    task.run(task=send_configs, command=cmd)
  File "/home/ilya/.local/lib/python3.10/site-packages/nornir/core/task.py", line 174, in run
    raise NornirSubTaskError(task=run_task, result=r)
nornir.core.exceptions.NornirSubTaskError: Subtask: send_configs (failed)


2023-02-13 09:36:45,200 - nornir.core.task -    ERROR -      start() - Host 'R6': task 'conf_command_list' failed with traceback:
Traceback (most recent call last):
  File "/home/ilya/.local/lib/python3.10/site-packages/nornir/core/task.py", line 99, in start
    r = self.task(self, **self.params)
  File "/home/ilya/Nornir_Labs/01_Essentials/05_Send_list_conf.py", line 11, in conf_command_list
    task.run(task=send_configs, command=cmd)
  File "/home/ilya/.local/lib/python3.10/site-packages/nornir/core/task.py", line 174, in run
    raise NornirSubTaskError(task=run_task, result=r)
nornir.core.exceptions.NornirSubTaskError: Subtask: send_configs (failed)


2023-02-13 09:36:45,200 - nornir.core.task -    ERROR -      start() - Host 'R7': task 'send_configs' failed with traceback:
Traceback (most recent call last):
  File "/home/ilya/.local/lib/python3.10/site-packages/nornir/core/task.py", line 99, in start
    r = self.task(self, **self.params)
TypeError: send_configs() got an unexpected keyword argument 'command'

2023-02-13 09:36:45,201 - nornir.core.task -    ERROR -      start() - Host 'R4': task 'conf_command_list' failed with traceback:
Traceback (most recent call last):
  File "/home/ilya/.local/lib/python3.10/site-packages/nornir/core/task.py", line 99, in start
    r = self.task(self, **self.params)
  File "/home/ilya/Nornir_Labs/01_Essentials/05_Send_list_conf.py", line 11, in conf_command_list
    task.run(task=send_configs, command=cmd)
  File "/home/ilya/.local/lib/python3.10/site-packages/nornir/core/task.py", line 174, in run
    raise NornirSubTaskError(task=run_task, result=r)
nornir.core.exceptions.NornirSubTaskError: Subtask: send_configs (failed)


2023-02-13 09:36:45,201 - nornir.core.task -    ERROR -      start() - Host 'R7': task 'conf_command_list' failed with traceback:
Traceback (most recent call last):
  File "/home/ilya/.local/lib/python3.10/site-packages/nornir/core/task.py", line 99, in start
    r = self.task(self, **self.params)
  File "/home/ilya/Nornir_Labs/01_Essentials/05_Send_list_conf.py", line 11, in conf_command_list
    task.run(task=send_configs, command=cmd)
  File "/home/ilya/.local/lib/python3.10/site-packages/nornir/core/task.py", line 174, in run
    raise NornirSubTaskError(task=run_task, result=r)
nornir.core.exceptions.NornirSubTaskError: Subtask: send_configs (failed)


2023-02-13 09:37:06,948 -  nornir.core -     INFO -        run() - Running task 'conf_command_list' with args {} on 7 hosts
2023-02-13 09:37:07,306 - nornir.core.task -    ERROR -      start() - Host 'R6': task 'send_configs' failed with traceback:
Traceback (most recent call last):
  File "/home/ilya/.local/lib/python3.10/site-packages/nornir/core/task.py", line 99, in start
    r = self.task(self, **self.params)
  File "/home/ilya/.local/lib/python3.10/site-packages/nornir_scrapli/tasks/core/send_configs.py", line 68, in send_configs
    scrapli_response = scrapli_conn.send_configs(
  File "/home/ilya/.local/lib/python3.10/site-packages/scrapli/driver/network/sync_driver.py", line 507, in send_configs
    resolved_privilege_level, failed_when_contains = self._pre_send_configs(
  File "/home/ilya/.local/lib/python3.10/site-packages/scrapli/driver/network/base_driver.py", line 544, in _pre_send_configs
    raise ScrapliTypeError(
scrapli.exceptions.ScrapliTypeError: 'send_configs' expects a list of strings, got <class 'str'>, to send a single configuration line/string use the 'send_config' method instead.

2023-02-13 09:37:07,307 - nornir.core.task -    ERROR -      start() - Host 'R6': task 'conf_command_list' failed with traceback:
Traceback (most recent call last):
  File "/home/ilya/.local/lib/python3.10/site-packages/nornir/core/task.py", line 99, in start
    r = self.task(self, **self.params)
  File "/home/ilya/Nornir_Labs/01_Essentials/05_Send_list_conf.py", line 11, in conf_command_list
    task.run(task=send_configs, configs=cmd)
  File "/home/ilya/.local/lib/python3.10/site-packages/nornir/core/task.py", line 174, in run
    raise NornirSubTaskError(task=run_task, result=r)
nornir.core.exceptions.NornirSubTaskError: Subtask: send_configs (failed)


2023-02-13 09:37:07,319 - nornir.core.task -    ERROR -      start() - Host 'R7': task 'send_configs' failed with traceback:
Traceback (most recent call last):
  File "/home/ilya/.local/lib/python3.10/site-packages/nornir/core/task.py", line 99, in start
    r = self.task(self, **self.params)
  File "/home/ilya/.local/lib/python3.10/site-packages/nornir_scrapli/tasks/core/send_configs.py", line 68, in send_configs
    scrapli_response = scrapli_conn.send_configs(
  File "/home/ilya/.local/lib/python3.10/site-packages/scrapli/driver/network/sync_driver.py", line 507, in send_configs
    resolved_privilege_level, failed_when_contains = self._pre_send_configs(
  File "/home/ilya/.local/lib/python3.10/site-packages/scrapli/driver/network/base_driver.py", line 544, in _pre_send_configs
    raise ScrapliTypeError(
scrapli.exceptions.ScrapliTypeError: 'send_configs' expects a list of strings, got <class 'str'>, to send a single configuration line/string use the 'send_config' method instead.

2023-02-13 09:37:07,319 - nornir.core.task -    ERROR -      start() - Host 'R7': task 'conf_command_list' failed with traceback:
Traceback (most recent call last):
  File "/home/ilya/.local/lib/python3.10/site-packages/nornir/core/task.py", line 99, in start
    r = self.task(self, **self.params)
  File "/home/ilya/Nornir_Labs/01_Essentials/05_Send_list_conf.py", line 11, in conf_command_list
    task.run(task=send_configs, configs=cmd)
  File "/home/ilya/.local/lib/python3.10/site-packages/nornir/core/task.py", line 174, in run
    raise NornirSubTaskError(task=run_task, result=r)
nornir.core.exceptions.NornirSubTaskError: Subtask: send_configs (failed)


2023-02-13 09:37:07,327 - nornir.core.task -    ERROR -      start() - Host 'R3': task 'send_configs' failed with traceback:
Traceback (most recent call last):
  File "/home/ilya/.local/lib/python3.10/site-packages/nornir/core/task.py", line 99, in start
    r = self.task(self, **self.params)
  File "/home/ilya/.local/lib/python3.10/site-packages/nornir_scrapli/tasks/core/send_configs.py", line 68, in send_configs
    scrapli_response = scrapli_conn.send_configs(
  File "/home/ilya/.local/lib/python3.10/site-packages/scrapli/driver/network/sync_driver.py", line 507, in send_configs
    resolved_privilege_level, failed_when_contains = self._pre_send_configs(
  File "/home/ilya/.local/lib/python3.10/site-packages/scrapli/driver/network/base_driver.py", line 544, in _pre_send_configs
    raise ScrapliTypeError(
scrapli.exceptions.ScrapliTypeError: 'send_configs' expects a list of strings, got <class 'str'>, to send a single configuration line/string use the 'send_config' method instead.

2023-02-13 09:37:07,328 - nornir.core.task -    ERROR -      start() - Host 'R3': task 'conf_command_list' failed with traceback:
Traceback (most recent call last):
  File "/home/ilya/.local/lib/python3.10/site-packages/nornir/core/task.py", line 99, in start
    r = self.task(self, **self.params)
  File "/home/ilya/Nornir_Labs/01_Essentials/05_Send_list_conf.py", line 11, in conf_command_list
    task.run(task=send_configs, configs=cmd)
  File "/home/ilya/.local/lib/python3.10/site-packages/nornir/core/task.py", line 174, in run
    raise NornirSubTaskError(task=run_task, result=r)
nornir.core.exceptions.NornirSubTaskError: Subtask: send_configs (failed)


2023-02-13 09:37:07,333 - nornir.core.task -    ERROR -      start() - Host 'R4': task 'send_configs' failed with traceback:
Traceback (most recent call last):
  File "/home/ilya/.local/lib/python3.10/site-packages/nornir/core/task.py", line 99, in start
    r = self.task(self, **self.params)
  File "/home/ilya/.local/lib/python3.10/site-packages/nornir_scrapli/tasks/core/send_configs.py", line 68, in send_configs
    scrapli_response = scrapli_conn.send_configs(
  File "/home/ilya/.local/lib/python3.10/site-packages/scrapli/driver/network/sync_driver.py", line 507, in send_configs
    resolved_privilege_level, failed_when_contains = self._pre_send_configs(
  File "/home/ilya/.local/lib/python3.10/site-packages/scrapli/driver/network/base_driver.py", line 544, in _pre_send_configs
    raise ScrapliTypeError(
scrapli.exceptions.ScrapliTypeError: 'send_configs' expects a list of strings, got <class 'str'>, to send a single configuration line/string use the 'send_config' method instead.

2023-02-13 09:37:07,334 - nornir.core.task -    ERROR -      start() - Host 'R4': task 'conf_command_list' failed with traceback:
Traceback (most recent call last):
  File "/home/ilya/.local/lib/python3.10/site-packages/nornir/core/task.py", line 99, in start
    r = self.task(self, **self.params)
  File "/home/ilya/Nornir_Labs/01_Essentials/05_Send_list_conf.py", line 11, in conf_command_list
    task.run(task=send_configs, configs=cmd)
  File "/home/ilya/.local/lib/python3.10/site-packages/nornir/core/task.py", line 174, in run
    raise NornirSubTaskError(task=run_task, result=r)
nornir.core.exceptions.NornirSubTaskError: Subtask: send_configs (failed)


2023-02-13 09:37:07,337 - nornir.core.task -    ERROR -      start() - Host 'R2': task 'send_configs' failed with traceback:
Traceback (most recent call last):
  File "/home/ilya/.local/lib/python3.10/site-packages/nornir/core/task.py", line 99, in start
    r = self.task(self, **self.params)
  File "/home/ilya/.local/lib/python3.10/site-packages/nornir_scrapli/tasks/core/send_configs.py", line 68, in send_configs
    scrapli_response = scrapli_conn.send_configs(
  File "/home/ilya/.local/lib/python3.10/site-packages/scrapli/driver/network/sync_driver.py", line 507, in send_configs
    resolved_privilege_level, failed_when_contains = self._pre_send_configs(
  File "/home/ilya/.local/lib/python3.10/site-packages/scrapli/driver/network/base_driver.py", line 544, in _pre_send_configs
    raise ScrapliTypeError(
scrapli.exceptions.ScrapliTypeError: 'send_configs' expects a list of strings, got <class 'str'>, to send a single configuration line/string use the 'send_config' method instead.

2023-02-13 09:37:07,337 - nornir.core.task -    ERROR -      start() - Host 'R2': task 'conf_command_list' failed with traceback:
Traceback (most recent call last):
  File "/home/ilya/.local/lib/python3.10/site-packages/nornir/core/task.py", line 99, in start
    r = self.task(self, **self.params)
  File "/home/ilya/Nornir_Labs/01_Essentials/05_Send_list_conf.py", line 11, in conf_command_list
    task.run(task=send_configs, configs=cmd)
  File "/home/ilya/.local/lib/python3.10/site-packages/nornir/core/task.py", line 174, in run
    raise NornirSubTaskError(task=run_task, result=r)
nornir.core.exceptions.NornirSubTaskError: Subtask: send_configs (failed)


2023-02-13 09:37:07,354 - nornir.core.task -    ERROR -      start() - Host 'R5': task 'send_configs' failed with traceback:
Traceback (most recent call last):
  File "/home/ilya/.local/lib/python3.10/site-packages/nornir/core/task.py", line 99, in start
    r = self.task(self, **self.params)
  File "/home/ilya/.local/lib/python3.10/site-packages/nornir_scrapli/tasks/core/send_configs.py", line 68, in send_configs
    scrapli_response = scrapli_conn.send_configs(
  File "/home/ilya/.local/lib/python3.10/site-packages/scrapli/driver/network/sync_driver.py", line 507, in send_configs
    resolved_privilege_level, failed_when_contains = self._pre_send_configs(
  File "/home/ilya/.local/lib/python3.10/site-packages/scrapli/driver/network/base_driver.py", line 544, in _pre_send_configs
    raise ScrapliTypeError(
scrapli.exceptions.ScrapliTypeError: 'send_configs' expects a list of strings, got <class 'str'>, to send a single configuration line/string use the 'send_config' method instead.

2023-02-13 09:37:07,354 - nornir.core.task -    ERROR -      start() - Host 'R5': task 'conf_command_list' failed with traceback:
Traceback (most recent call last):
  File "/home/ilya/.local/lib/python3.10/site-packages/nornir/core/task.py", line 99, in start
    r = self.task(self, **self.params)
  File "/home/ilya/Nornir_Labs/01_Essentials/05_Send_list_conf.py", line 11, in conf_command_list
    task.run(task=send_configs, configs=cmd)
  File "/home/ilya/.local/lib/python3.10/site-packages/nornir/core/task.py", line 174, in run
    raise NornirSubTaskError(task=run_task, result=r)
nornir.core.exceptions.NornirSubTaskError: Subtask: send_configs (failed)


2023-02-13 09:37:09,248 - nornir.core.task -    ERROR -      start() - Host 'R1': task 'send_configs' failed with traceback:
Traceback (most recent call last):
  File "/home/ilya/.local/lib/python3.10/site-packages/nornir/core/task.py", line 99, in start
    r = self.task(self, **self.params)
  File "/home/ilya/.local/lib/python3.10/site-packages/nornir_scrapli/tasks/core/send_configs.py", line 68, in send_configs
    scrapli_response = scrapli_conn.send_configs(
  File "/home/ilya/.local/lib/python3.10/site-packages/scrapli/driver/network/sync_driver.py", line 507, in send_configs
    resolved_privilege_level, failed_when_contains = self._pre_send_configs(
  File "/home/ilya/.local/lib/python3.10/site-packages/scrapli/driver/network/base_driver.py", line 544, in _pre_send_configs
    raise ScrapliTypeError(
scrapli.exceptions.ScrapliTypeError: 'send_configs' expects a list of strings, got <class 'str'>, to send a single configuration line/string use the 'send_config' method instead.

2023-02-13 09:37:09,249 - nornir.core.task -    ERROR -      start() - Host 'R1': task 'conf_command_list' failed with traceback:
Traceback (most recent call last):
  File "/home/ilya/.local/lib/python3.10/site-packages/nornir/core/task.py", line 99, in start
    r = self.task(self, **self.params)
  File "/home/ilya/Nornir_Labs/01_Essentials/05_Send_list_conf.py", line 11, in conf_command_list
    task.run(task=send_configs, configs=cmd)
  File "/home/ilya/.local/lib/python3.10/site-packages/nornir/core/task.py", line 174, in run
    raise NornirSubTaskError(task=run_task, result=r)
nornir.core.exceptions.NornirSubTaskError: Subtask: send_configs (failed)


2023-02-13 09:38:07,209 -  nornir.core -     INFO -        run() - Running task 'conf_command_list' with args {} on 7 hosts
2023-02-13 09:46:33,623 -  nornir.core -     INFO -        run() - Running task 'show_command_list' with args {} on 7 hosts
2023-02-13 09:46:48,672 - nornir.core.task -    ERROR -      start() - Host 'R5': task 'send_command' failed with traceback:
Traceback (most recent call last):
  File "/home/ilya/.local/lib/python3.10/site-packages/nornir/core/task.py", line 99, in start
    r = self.task(self, **self.params)
  File "/home/ilya/.local/lib/python3.10/site-packages/nornir_scrapli/tasks/core/send_command.py", line 36, in send_command
    scrapli_conn = task.host.get_connection("scrapli", task.nornir.config)
  File "/home/ilya/.local/lib/python3.10/site-packages/nornir/core/inventory.py", line 494, in get_connection
    self.open_connection(
  File "/home/ilya/.local/lib/python3.10/site-packages/nornir/core/inventory.py", line 546, in open_connection
    conn_obj.open(
  File "/home/ilya/.local/lib/python3.10/site-packages/nornir_scrapli/connection.py", line 105, in open
    connection.open()
  File "/home/ilya/.local/lib/python3.10/site-packages/scrapli/driver/base/sync_driver.py", line 88, in open
    self.channel.channel_authenticate_ssh(
  File "/home/ilya/.local/lib/python3.10/site-packages/scrapli/decorators.py", line 216, in decorate
    return _multiprocessing_timeout(
  File "/home/ilya/.local/lib/python3.10/site-packages/scrapli/decorators.py", line 113, in _multiprocessing_timeout
    return future.result()
  File "/usr/lib/python3.10/concurrent/futures/_base.py", line 451, in result
    return self.__get_result()
  File "/usr/lib/python3.10/concurrent/futures/_base.py", line 403, in __get_result
    raise self._exception
  File "/usr/lib/python3.10/concurrent/futures/thread.py", line 58, in run
    result = self.fn(*self.args, **self.kwargs)
  File "/home/ilya/.local/lib/python3.10/site-packages/scrapli/channel/sync_channel.py", line 290, in channel_authenticate_ssh
    self._ssh_message_handler(output=authenticate_buf)
  File "/home/ilya/.local/lib/python3.10/site-packages/scrapli/channel/base_channel.py", line 432, in _ssh_message_handler
    raise ScrapliAuthenticationFailed(msg)
scrapli.exceptions.ScrapliAuthenticationFailed: Timed out connecting to host

2023-02-13 09:46:48,672 - nornir.core.task -    ERROR -      start() - Host 'R5': task 'show_command_list' failed with traceback:
Traceback (most recent call last):
  File "/home/ilya/.local/lib/python3.10/site-packages/nornir/core/task.py", line 99, in start
    r = self.task(self, **self.params)
  File "/home/ilya/Nornir_Labs/01_Essentials/04_Send_list_show.py", line 13, in show_command_list
    task.run(task=send_command, command=cmd)
  File "/home/ilya/.local/lib/python3.10/site-packages/nornir/core/task.py", line 174, in run
    raise NornirSubTaskError(task=run_task, result=r)
nornir.core.exceptions.NornirSubTaskError: Subtask: send_command (failed)


2023-02-13 09:53:27,189 -  nornir.core -     INFO -        run() - Running task 'set_ip_gig2' with args {} on 2 hosts
2023-02-13 09:53:27,583 -  nornir.core -     INFO -        run() - Running task 'set_ip_gig3' with args {} on 2 hosts
2023-02-13 09:53:27,652 -  nornir.core -     INFO -        run() - Running task 'set_ip_gig4' with args {} on 2 hosts
2023-02-13 09:53:27,750 -  nornir.core -     INFO -        run() - Running task 'set_ip_gig5' with args {} on 2 hosts
2023-02-13 09:53:57,109 -  nornir.core -     INFO -        run() - Running task 'show_command_list' with args {} on 2 hosts
2023-02-13 10:01:14,866 -  nornir.core -     INFO -        run() - Running task 'show_command_list' with args {} on 2 hosts
2023-02-13 10:03:29,933 -  nornir.core -     INFO -        run() - Running task 'set_ip_gig2' with args {} on 2 hosts
2023-02-13 10:03:30,324 -  nornir.core -     INFO -        run() - Running task 'set_ip_gig3' with args {} on 2 hosts
2023-02-13 10:03:30,383 -  nornir.core -     INFO -        run() - Running task 'set_ip_gig4' with args {} on 2 hosts
2023-02-13 10:03:30,442 -  nornir.core -     INFO -        run() - Running task 'set_ip_gig5' with args {} on 2 hosts
2023-02-13 10:04:53,765 -  nornir.core -     INFO -        run() - Running task 'set_ip_gig2' with args {} on 2 hosts
2023-02-13 10:04:54,163 -  nornir.core -     INFO -        run() - Running task 'set_ip_gig3' with args {} on 2 hosts
2023-02-13 10:04:54,234 -  nornir.core -     INFO -        run() - Running task 'set_ip_gig4' with args {} on 2 hosts
2023-02-13 10:04:54,298 -  nornir.core -     INFO -        run() - Running task 'set_ip_gig5' with args {} on 2 hosts
2023-02-13 10:25:35,581 -  nornir.core -     INFO -        run() - Running task 'show_command_list' with args {} on 7 hosts
2023-02-13 10:26:39,258 -  nornir.core -     INFO -        run() - Running task 'set_ip_gig2' with args {} on 7 hosts
2023-02-13 10:26:39,950 -  nornir.core -     INFO -        run() - Running task 'set_ip_gig3' with args {} on 7 hosts
2023-02-13 10:26:40,144 -  nornir.core -     INFO -        run() - Running task 'set_ip_gig4' with args {} on 7 hosts
2023-02-13 10:26:40,281 -  nornir.core -     INFO -        run() - Running task 'set_ip_gig5' with args {} on 7 hosts
2023-02-13 10:26:40,390 -  nornir.core -     INFO -        run() - Running task 'set_ip_loop0' with args {} on 7 hosts
2023-02-13 10:26:53,975 -  nornir.core -     INFO -        run() - Running task 'show_command_list' with args {} on 7 hosts
2023-02-13 10:30:22,444 -  nornir.core -     INFO -        run() - Running task 'conf_command_list' with args {} on 7 hosts
2023-02-13 10:31:12,725 -  nornir.core -     INFO -        run() - Running task 'set_ip_gig2' with args {} on 7 hosts
2023-02-13 10:31:13,403 -  nornir.core -     INFO -        run() - Running task 'set_ip_gig3' with args {} on 7 hosts
2023-02-13 10:31:13,587 -  nornir.core -     INFO -        run() - Running task 'set_ip_gig4' with args {} on 7 hosts
2023-02-13 10:31:13,727 -  nornir.core -     INFO -        run() - Running task 'set_ip_gig5' with args {} on 7 hosts
2023-02-13 10:31:13,848 -  nornir.core -     INFO -        run() - Running task 'set_ip_loop0' with args {} on 7 hosts
2023-02-13 10:33:49,307 -  nornir.core -     INFO -        run() - Running task 'show_command_list' with args {} on 7 hosts
2023-02-13 10:36:19,636 -  nornir.core -     INFO -        run() - Running task 'backup_run_flash' with args {} on 7 hosts
